Workbook

Sheet 00_README
A1: FSAE EV — Suspension Sizing Tool | Fase 1
A3: Versão do workbook: V2.5 (revisão metodológica contra Milliken/Gillespie/Seward/Pacejka: pneu em série, termo gravitacional da rolagem, massa suspensa por eixo, anti com sinal, Ky com um λFz0; EDR-045 a EDR-049) | Status: DRAFT — cross-check, ainda NÃO REFERENCE-validated
A5: O que este workbook é (e o que não é)
A6: Este workbook implementa, em fórmulas nativas do Excel, as mesmas equações do Engineering Standard V2.0
A7: (SUS-001 a SUS-104, SUS-201/202/205/206/207/208, SUS-501/502/503, SUS-701/702), já verificadas no piloto Python
A8: (suspension_model_V2_1.py, tire_model_V2_2.py e seus testes; ver 13_VALIDATION).
A10: Isso NÃO substitui o Python como motor de referência. O Data Contract V2.0 continua definindo o fluxo
A11: Excel -> input.json -> Python -> results.json -> Excel para quando o bridge automático existir (Fase 2+).
A12: Até lá, este Excel é uma segunda implementação independente das MESMAS equações, útil para uso diário
A13: e como cross-check contra o Python — igual ao que já fazemos com RC/MR (REFERENCE vs. MODEL/CHECK).
A15: Legenda de cores
A16: ■ Azul | B16: INPUT — editável pelo usuário
A17: ■ Verde-teal | B17: REFERENCE — vem do CAD/hardpoints (digitado manualmente até a Fase 2 ter Power Query)
A18: ■ Laranja + fundo | B18: PROVISÓRIO — normalmente viria do OptimumKinematics (Fase 2); input manual temporário
A19: ■ Preto + fundo cinza | B19: CALCULATED — fórmula, não editar
A20: ■ Amarelo | B20: Hipótese-chave / célula de atenção
A22: Convenções congeladas (Engineering Standard, seção 4 e 17)
A23: • Sistema de coordenadas: ISO 8855 — X positivo para frente, Y positivo para esquerda, Z positivo para cima.
A24: • Pitch positivo = nariz descendo. Roll positivo = lado esquerdo sobe. Yaw positivo = anti-horário visto de cima.
A25: • Motion Ratio = deslocamento da roda / deslocamento da mola (MR [wheel/spring]).
A26: • Camber positivo = topo da roda para fora. Toe positivo = toe-out.
A27: • a_x positivo = aceleração para frente (transfere carga para trás). a_y positivo = para a esquerda (lado direito ganha carga).
A28: • SUS-000 (referência de solo): todas as alturas (h_CG, h_s, h_uF, h_uR, RC) são medidas a partir do solo, não da origem do CAD.
A30: Limitações conhecidas da V1.0 (declaradas, não escondidas)
A31: • Quase-estático: sem dinâmica transiente, sem modelo de amortecedor.
A32: • RC tratado como ponto fixo no ride height estático — migração de RC durante rolagem não modelada.
A33: • Aero fixo por Setup (sem F_aero(v)) — decisão congelada para V1.
A34: • Anti-dive/Anti-squat (SUS-301/302) estão implementados em 06_SUSPENSION, mas com FB_f, TF_r e Instant Center PLACEHOLDER (07_KINEMATICS) — não são valores reais do carro; a linha geométrica (contact patch vs. wheel center) ainda depende da configuração real de freio/trem de força. V2.0: o método de IC lateral e a forma sem sinal de tan(φ) usados nestas fórmulas são os da V1 (Standard V2.0, notas de SUS-406/301/302: mal condicionado e sem sinal físico); os valores seguem PLACEHOLDER e não representam o carro.
... A37: • Pneu (10_TIRE): coeficientes de um .tir TTC PROVISÓRIO (pode não ser o pneu real); arquivo em SAE (TTC, declarado) transformado para ISO, sinal de camber não confirmado; sem Mx/My/Mz, pressão ou relaxamento; fora da faixa do dataset o resultado é N/A. μ efetivo é derivado do dataset, não medido pela equipe.

Sheet 01_SETUP
A1: 01_SETUP
A3: Setup ativo
A4: Setup ID | B4: S-001
A5: Nome do Setup | B5: Baseline
A6: Notas | B6: Setup de referência para o piloto
A8: Revisões (DEC-012 — cada domínio é independente)
A9: Geometry REV | B9: G-REV-A
A10: Kinematics REV | B10: N/A (Fase 2)
A11: Tire REV | B11: T-REV-A (provisório)
A12: Dynamics Script Version | B12: V2.0

Sheet 02_REQUIREMENTS
A1: 02_REQUIREMENTS
A3: Requisitos do Rulebook (FSAE Rules 2026 V1.0) pertinentes ao domínio já modelado
A4: ID | B4: Requirement | C4: Value | D4: Type | E4: Source | F4: Status | G4: Owner | H4: Revision
A5: REQ-001 | B5: Wheelbase mínimo (SUS-003) | C5: >= 1525 mm | D5: Geometry | E5: Rulebook V.1.2 | F5: ACTIVE | G5: N/A (externo) | H5: FSAE Rules 2026 V1.0
A6: REQ-002 | B6: Razão entre bitolas (SUS-004/SUS-005): a menor não pode ser < 75% da maior | C6: >= 0.75 (menor/maior) | D6: Geometry | E6: Rulebook V.1.3.2 | F6: ACTIVE | G6: N/A (externo) | H6: FSAE Rules 2026 V1.0
A7: REQ-003 | B7: Estabilidade ao capotamento: bitola + CG (SUS-002, SUS-004/005) devem combinar para o veículo não capotar no Tilt Test | C7: não capota a 60° de inclinação (~1.7g lateral equivalente) | D7: Safety | E7: Rulebook V.1.3.1 + IN.11.2.2 (Tilt Test) | F7: ACTIVE | G7: N/A (externo) | H7: FSAE Rules 2026 V1.0
A8: REQ-004 | B8: Curso útil mínimo de suspensão, dianteiro e traseiro, com piloto sentado | C8: >= 50 mm | D8: Competition | E8: Rulebook V.3.1.1 | F8: ACTIVE | G8: N/A (externo) | H8: FSAE Rules 2026 V1.0
A9: REQ-005 | B9: Diâmetro mínimo de roda (afeta estimativa de altura de CG não-suspenso, SUS-010/011) | C9: >= 203.2 mm (8.0 in) | D9: Components | E9: Rulebook V.4.1 | F9: ACTIVE | G9: N/A (externo) | H9: FSAE Rules 2026 V1.0
A10: REQ-006 | B10: Sistema de freio deve travar as 4 rodas com controle único e 2 circuitos hidráulicos independentes; para EV, ate 90% do curso do pedal pode ser regenerativo antes de acionar o hidraulico (contexto para SUS-013) | C10: 4 rodas / 2 circuitos / 90% pedal regen (EV) | D10: Safety | E10: Rulebook T.3.1.2, T.3.1.3, T.3.2.4 | F10: ACTIVE | G10: N/A (externo) | H10: FSAE Rules 2026 V1.0
A12: Requisitos acima vêm exclusivamente do Rulebook (FSAE Rules 2026 V1.0) - citação de regra exata em cada linha.
A13: Restrições próprias da equipe (Team/Packaging/Manufacturing) ainda NÃO foram definidas - serão adicionadas quando a equipe as fornecer, não antes.

Sheet 03_TARGETS
A1: 03_TARGETS
A3: Targets (aquilo que a equipe quer atingir) — ESTRUTURA, sem valores inventados
A4: ID | B4: Parameter | C4: Target | D4: Status | E4: Owner | F4: Decision | G4: Revision
A5: TARGET-001 | B5: Front Natural Frequency (SUS-205) | C5: TBD | D5: OPEN | E5: TBD | F5: - | G5: -
A6: TARGET-002 | B6: Rear Natural Frequency (SUS-205) | C6: TBD | D6: OPEN | E6: TBD | F6: - | G6: -
A7: TARGET-003 | B7: Roll Stiffness Distribution - lambda_f (SUS-208) | C7: TBD | D7: OPEN | E7: TBD | F7: - | G7: -
A8: TARGET-004 | B8: Anti-Dive % (SUS-301) | C8: TBD | D8: OPEN | E8: TBD | F8: - | G8: -
A9: TARGET-005 | B9: Anti-Squat % (SUS-302) | C9: TBD | D9: OPEN | E9: TBD | F9: - | G9: -
A11: 'Target' = TBD e Status = OPEN deliberadamente: nenhum valor-alvo real foi definido pela equipe ainda.
A12: Parametros como Motion Ratio, Spring Rate e Wheel Rate NAO viram Target aqui de proposito - sao consequencia de geometria/packaging/Design Mode, nao objetivos primarios.

Sheet 04_DECISION_REGISTER
A1: 04_DECISION_REGISTER
A3: Decisões já tomadas (arquitetura/física da V1) — registro consolidado (planilha + Guide, Apêndice E)
A4: ID | B4: Target/Escopo | C4: Decision | D4: Why | E4: Constraints | F4: Owner | G4: Status | H4: Origem
A5: DR-001 | B5: Convenções (todos os SUS-XXX) | C5: Sistema de coordenadas ISO 8855 (X-frente, Y-esquerda, Z-cima), destrogiro, sinais por regra da mao direita sem excecao intuitiva. | D5: Padrao internacional de dinamica veicular; evita ambiguidade entre pitch/roll/yaw ao importar dados de ferramentas externas. | E5: Compatibilidade com OptimumKinematics (configuravel) e Lotus (requer adapter de sinal). | F5: Mecanica (decisao de arquitetura) | G5: FROZEN | H5: Planilha + Guide
A6: DR-002 | B6: SUS-201/202 | C6: Motion Ratio definido como wheel travel / spring travel (nao a convencao inversa). | D6: Convencao unica evita erro de fator ao converter Ks<->Kw; nomenclatura explicita 'MR [wheel/spring]' obrigatoria. | E6: Nenhuma - decisao de nomenclatura interna. | F6: Mecanica (decisao de arquitetura) | G6: FROZEN | H6: Planilha + Guide
A7: DR-003 | B7: SUS-103 | C7: Modelo de duas molas de Milliken adotado como formulacao de referencia para transferencia lateral de carga. | D7: Formulacao padrao da literatura (Milliken, RCVD); verificada algebricamente (conservacao de momento), numericamente (Python+Excel) e cross-referenciada contra Chalmers/Sampo (transcricao identica termo a termo). | E7: Hipotese de superposicao linear; RC estatico (sem migracao dinamica). | F7: Mecanica (decisao de arquitetura) | G7: FROZEN | H7: Planilha + Guide
A8: DR-004 | B8: Todo o dominio de suspensao | C8: T09/E03 e a referencia historica de suspensao; TX/E05 nao contamina o baseline de dados de suspensao. | D8: Dados de suspensao do TX se mostraram parcialmente estimados/inconsistentes (ex.: ARB documentado mas nao efetivamente implementado); T09 tem planilha de calculo detalhada verificavel. | E8: Dados gerais de veiculo (massa, geometria) do TX permanecem utilizaveis quando o Design Case for aberto - a exclusao e so para comportamento/configuracao de suspensao. | F8: Mecanica (decisao de arquitetura) | G8: FROZEN | H8: Planilha + Guide
A9: DR-005 | B9: SUS-401 (Roll Center) | C9: V1 usa RC_static = RC(z_RH); sem migracao dinamica do roll center durante rolagem. | D9: Modelagem de RC(phi) exigiria acoplamento iterativo Vehicle State <-> KOP, fora do escopo da V1. | E9: Limitacao conhecida e documentada; OptimumKinematics assume essa responsabilidade na V2. | F9: Mecanica (decisao de arquitetura) | G9: FROZEN | H9: Planilha + Guide
A10: DR-006 | B10: SUS-301/SUS-302 | C10: Anti-dive e anti-squat nao alteram a magnitude da transferencia de carga longitudinal global - so descrevem a particao geometrica vs. elastica da reacao. | D10: Erro classico de interpretacao seria multiplicar o load transfer por (1-%AD); isso e fisicamente incorreto sob equilibrio de corpo rigido. | E10: Nenhuma equacao de load transfer deve referenciar %AD/%AS como fator multiplicativo. | F10: Mecanica (decisao de arquitetura) | G10: FROZEN | H10: Planilha + Guide
A11: DR-007 | B11: SUS-701/SUS-702 | C11: Aero da V1 limitado a downforce total + aero balance dianteiro, ambos constantes por Setup (sem F_aero(v), sem CFD). | D11: Evita 'fisica implicita' no Excel sem Engineering Standard formal para aero dependente de velocidade. | E11: Se aero dependente de velocidade for necessario no futuro, exige nova ficha SUS-7XX formal antes de implementar. | F11: Mecanica (decisao de arquitetura) | G11: FROZEN | H11: Planilha + Guide
A12: DR-008 | B12: Arquitetura Excel/Python | C12: Nenhuma bridge automatica Python<->Excel na V1; Excel possui implementacao propria das formulas, Python e motor independente, ambos comparados manualmente. | D12: Bridge JSON/CSV e um projeto proprio; construir isso antes de validar o modelo fisico inverteria a prioridade. | E12: Quando a bridge existir, as formulas do Excel permanecem como cross-check independente, nao sao descartadas. | F12: Mecanica (decisao de arquitetura) | G12: n/d | H12: Planilha
A13: DR-009 | B13: SUS-402 e SUS-406 (início da V2) | C13: SUS-402 (Roll Center via IC em vista frontal) e SUS-406 (Instant Center em vista lateral, para Anti-Dive/Anti-Squat) formalizados e implementados apenas em Python (kinematics_model_V2_0.py), nao em formula nativa do Excel. | D13: A dupla interseccao de retas 2D produziria uma formula de planilha longa e ilegivel; verificado com casos de teste sinteticos (11/11 PASS no total, incluindo simetria de espelhamento e casos degenerados de retas paralelas) antes de qualquer hardpoint real existir. SUS-406 usa ponto medio das buchas como proxy do eixo de pivo em vista lateral (diferente do SUS-402, que usa o mesmo ponto para vista frontal) - aproximacao de primeira ordem documentada na ficha. Guide (DR-009): solver cinematico interno fora da V1, motivo "evitar duplicacao". | E13: Nunca autoritativo (Data Type MODEL, proposito cross-check) - OptimumKinematics continua sendo REFERENCE oficial (SUS-401/SUS-406) quando integrado. Ainda nao conectado ao Excel - aguarda o hardpoint schema (proximo passo da V2). | F13: Mecanica (decisao de arquitetura) | G13: FROZEN | H13: Planilha + Guide (Guide: DR-009)
A14: DR-010 | B14: SUS-202 / SUS-205 (Design Mode) | C14: Design Mode explicito: o calculo reverso deve indicar qual variavel e o alvo e qual e resolvida; sem goal seek opaco. | D14: Evitar goal seek opaco e o uso da mesma equacao no sentido errado (Guide, Apendice B.3). | E14: Design Mode nao cria fichas proprias: e a equacao reversa dentro de SUS-202/205 (Engineering Standard, Bloco J). Equacao reversa de roll stiffness (SUS-206/207) ainda nao escrita no Standard. Valores de 2,5/2,7 Hz e lambda_f 0,55 em 11_DESIGN sao demonstrativos, nao TARGET (Guide, cap. 4.11 e Apendice F.2). | F14: Mecanica (decisao de arquitetura) | G14: FROZEN | H14: Guide
A15: DR-011 | B15: SUS-501 / SUS-502 / SUS-503 (Tire) | C15: Pneu consumido como REFERENCE (OptimumTire/TTC), sem ajuste (fit) proprio na V1. | D15: Sem fit proprio na V1 (Guide, Apendice E). Numeracao: no Guide esta decisao aparece como DR-008. | E15: Nivel 1 (lookup) ou nivel 2 (parametrico) conforme DEC-007 (Engineering Standard). Verificar a convencao de sinal de alpha e de slip ratio exportada contra ISO 8855 antes de consumir. 10_TIRE implementado na V2.2 com dataset provisorio (ver DR-013). | F15: Mecanica (decisao de arquitetura) | G15: FROZEN | H15: Guide
... A17: DR-013 | B17: SUS-501 / SUS-502 / SUS-503 (Tire) — implementação em 10_TIRE | C17: Pneu avaliado em 10_TIRE por nivel 2 (parametrico): equacoes PAC2002/MF 5.2 aplicadas aos coeficientes de um .tir, sem fit proprio. Dataset atual = .tir TTC PROVISORIO (Hoosier R25B), so para desenvolvimento. Fora da faixa do dataset o resultado e N/A (sem extrapolar). | D17: Pedido do usuario (2026-10-12) com .tir TTC fornecido; DR-011 (sem fit proprio). Guia: o workbook nao apresenta mu proprio como medido. | E17: Sistema de eixos do arquivo = SAE (Calspan/TTC), DECLARADO pelo usuario (dados baixados do TTC), transformado para ISO (alpha_arq=-alpha, Fy_ISO=-Fy_arq; camber: empuxo para o lado da inclinacao, INFERIDO: IA do TTC nao verificado). Espelhamento das rodas esquerdas (arquivo e Right) e hipotese de projeto. Equacoes: verificadas (V2.3) contra duas implementacoes de terceiros (Racer CalcMF52 e ramo MF5.2 do MFeval; 3000 pontos, dif <= 3e-4 N) e por limites analiticos (tire_model_V2_2.py); NAO validadas contra o livro (Pacejka) nem contra medicao/OptimumTire: Validation = NOT_VALIDATED. Mx/My/Mz, pressao e relaxamento fora de escopo. | F17: Mecanica (decisao de implementacao) | G17: DRAFT | H17: V2.2 (proposta); texto revisado na V2.3 e V2.4
A18: Status = Estado do Guide (Apendice E.1). DR-008 nao tem estado registrado em nenhum documento (n/d). Origem "Guide" = decisao que so existia no Guide.
A19: Fonte oficial consolidada de decisões: Engineering_Decision_Register.md (EDR-xxx). Esta aba é espelho resumido (DR-xxx); em caso de divergência, vale o EDR.

Sheet 05_VEHICLE
A1: 05_VEHICLE
A3: Massa e Geometria
A4: Massa total (com piloto) | B4: 316.5 | C4: kg | D4: SUS-001
A5: Altura do CG (total) | B5: 0.315 | C5: m | D5: SUS-002
A6: Wheelbase (L) | B6: 1.594 | C6: m | D6: SUS-003
A7: Front Track (t_F) | B7: 1.277 | C7: m | D7: SUS-004
A8: Rear Track (t_R) | B8: 1.271 | C8: m | D8: SUS-005
A9: CG -> eixo dianteiro (a) | B9: 0.82203 | C9: m | D9: SUS-006
A10: CG -> eixo traseiro (b) | B10: 0.77197 | C10: m | D10: SUS-006
A11: Checagem: a + b = L (deve ser 0) | B11: ='05_VEHICLE'!$B$9+'05_VEHICLE'!$B$10-'05_VEHICLE'!$B$6
A13: Massas não-suspensas
A14: Massa não-suspensa dianteira | B14: 15 | C14: kg | D14: SUS-007
A15: Massa não-suspensa traseira | B15: 18 | C15: kg | D15: SUS-008
A16: Altura CG não-suspenso dianteiro | B16: 0.254 | C16: m | D16: SUS-010
A17: Altura CG não-suspenso traseiro | B17: 0.254 | C17: m | D17: SUS-011
A19: Referência de solo
A20: Ground Plane Z (offset origem CAD -> solo) | B20: -0.05 | C20: m | D20: SUS-000
A22: Calculado (SUS-009 / SUS-012)
A23: Massa suspensa total | B23: ='05_VEHICLE'!$B$4-'05_VEHICLE'!$B$14-'05_VEHICLE'!$B$15 | C23: kg | D23: SUS-009
A24: Altura do CG suspenso (h_s) | B24: =('05_VEHICLE'!$B$4*'05_VEHICLE'!$B$5-'05_VEHICLE'!$B$14*'05_VEHICLE'!$B$16-'05_VEHICLE'!$B$15*'05_VEHICLE'!$B$17)/'05_VEHICLE'!$B$23 | C24: m | D24: SUS-012
A25: Massa suspensa - eixo dianteiro (m·b/L − m_uF) | B25: ='05_VEHICLE'!$B$4*'05_VEHICLE'!$B$10/'05_VEHICLE'!$B$6-'05_VEHICLE'!$B$14 | C25: kg | D25: SUS-009
A26: Massa suspensa - eixo traseiro (m·a/L − m_uR) | B26: ='05_VEHICLE'!$B$4*'05_VEHICLE'!$B$9/'05_VEHICLE'!$B$6-'05_VEHICLE'!$B$15 | C26: kg | D26: SUS-009
A27: CG suspenso -> eixo dianteiro (a_s = L·m_s,R/m_s) | B27: ='05_VEHICLE'!$B$6*'05_VEHICLE'!$B$26/'05_VEHICLE'!$B$23 | C27: m | D27: SUS-009

Sheet 06_SUSPENSION
A1: 06_SUSPENSION
A2: Mola, MR, barra e roll center (B4:B15): valores DEMONSTRATIVOS herdados do T09/E03, para referência e teste das fórmulas; não são o TX/E05 (EDR-012/022).
A3: Mola / Motion Ratio
A4: Spring Rate dianteiro | B4: 49909.24 | C4: N/m | D4: SUS-203
A5: Spring Rate traseiro | B5: 57052.22 | C5: N/m | D5: SUS-203
A6: Motion Ratio dianteiro [wheel/spring] | B6: 1.76 | C6: - | D6: SUS-201
A7: Motion Ratio traseiro [wheel/spring] | B7: 1.76 | C7: - | D7: SUS-201
A9: Anti-Roll Bar (simplificação V1 — sem cinemática interna)
A10: K_ARB dianteiro | B10: 5012.32 | C10: N*m/rad | D10: SUS-206
A11: K_ARB traseiro | B11: 10.78 | C11: N*m/rad | D11: SUS-207
A13: Roll Center — PROVISÓRIO (Fase 2 substitui por REFERENCE do OptimumKinematics)
A14: Roll Center dianteiro (RH estático) | B14: 0.0675 | C14: m | D14: SUS-401-F
A15: Roll Center traseiro (RH estático) | B15: 0.11 | C15: m | D15: SUS-401-R
A17: Calculado — Wheel Rate / Roll Stiffness (SUS-202/206/207/208)
A18: Wheel Rate dianteiro | B18: ='06_SUSPENSION'!$B$4/'06_SUSPENSION'!$B$6^2 | C18: N/m | D18: SUS-202
A19: Wheel Rate traseiro | B19: ='06_SUSPENSION'!$B$5/'06_SUSPENSION'!$B$7^2 | C19: N/m | D19: SUS-202
A20: Roll Stiffness sem ARB e sem pneu (K_W·t_F²/2) - dianteira | B20: ='06_SUSPENSION'!$B$18*'05_VEHICLE'!$B$7^2/2 | C20: N*m/rad | D20: SUS-206
A21: Roll Stiffness sem ARB e sem pneu (K_W·t_R²/2) - traseira | B21: ='06_SUSPENSION'!$B$19*'05_VEHICLE'!$B$8^2/2 | C21: N*m/rad | D21: SUS-207
A22: Roll Stiffness dianteira K_phiF = (K_W·t²/2 + K_ARB) em série com K_T·t²/2 | B22: =1/(1/('06_SUSPENSION'!$B$20+'06_SUSPENSION'!$B$10)+1/'06_SUSPENSION'!$B$51) | C22: N*m/rad | D22: SUS-206
A23: Roll Stiffness traseira K_phiR = (K_W·t²/2 + K_ARB) em série com K_T·t²/2 | B23: =1/(1/('06_SUSPENSION'!$B$21+'06_SUSPENSION'!$B$11)+1/'06_SUSPENSION'!$B$52) | C23: N*m/rad | D23: SUS-207
A24: Distribuição de rigidez - dianteira (lambda_f) | B24: ='06_SUSPENSION'!$B$22/('06_SUSPENSION'!$B$22+'06_SUSPENSION'!$B$23) | C24: - | D24: SUS-208
A25: Distribuição de rigidez - traseira (lambda_r) | B25: ='06_SUSPENSION'!$B$23/('06_SUSPENSION'!$B$22+'06_SUSPENSION'!$B$23) | C25: - | D25: SUS-208
A27: Massa suspensa por canto (SUS-009, por eixo: (m·b/L − m_uF)/2 e (m·a/L − m_uR)/2)
A28: Massa suspensa por canto - dianteira | B28: ='05_VEHICLE'!$B$25/2 | C28: kg | D28: SUS-009
A29: Massa suspensa por canto - traseira | B29: ='05_VEHICLE'!$B$26/2 | C29: kg | D29: SUS-009
A31: Frequência Natural (SUS-205) — com a ride rate (pneu em série)
A32: Frequência Natural dianteira | B32: =(1/(2*PI()))*SQRT('06_SUSPENSION'!$B$49/'06_SUSPENSION'!$B$28) | C32: Hz | D32: SUS-205
A33: Frequência Natural traseira | B33: =(1/(2*PI()))*SQRT('06_SUSPENSION'!$B$50/'06_SUSPENSION'!$B$29) | C33: Hz | D33: SUS-205
A34: Anti-Dive / Anti-Squat (SUS-301/302) — com sinal (EDR-026/048)
A35: Milliken p. 618-619: freio no cubo (outboard) -> linha pelo contact patch; motor no chassi com semieixos -> linha pelo centro da roda (Fig. 17.15b). + = anti, − = pro (p. 620). IC de 07_KINEMATICS ainda é PLACEHOLDER.
A36: Front Brake Force Fraction (FB_f) | B36: 0.6 | C36: - | D36: SUS-013
A37: Rear Traction Force Fraction (TF_r) | B37: 1 | C37: - | D37: SUS-014
A38: Inclinação dz/dx da linha contact patch -> IC lateral dianteiro (com sinal; freio no cubo) | B38: ='07_KINEMATICS'!$B$10/'07_KINEMATICS'!$B$11 | C38: - | D38: SUS-406-F
A39: Inclinação dz/dx da linha centro da roda -> IC lateral traseiro (com sinal; motor no chassi) | B39: =('07_KINEMATICS'!$B$12-'07_KINEMATICS'!$B$14)/'07_KINEMATICS'!$B$13 | C39: - | D39: SUS-406-R
A40: Anti-Dive (%) = FB_f·(−dz/dx)·L/h·100 (+ = anti, − = pro-dive) | B40: ='06_SUSPENSION'!$B$36*(-'06_SUSPENSION'!$B$38)*('05_VEHICLE'!$B$6/'05_VEHICLE'!$B$5)*100 | C40: % | D40: SUS-301
A41: Anti-Squat (%) = TF_r·(dz/dx)·L/h·100 (+ = anti, − = pro-squat) | B41: ='06_SUSPENSION'!$B$37*'06_SUSPENSION'!$B$39*('05_VEHICLE'!$B$6/'05_VEHICLE'!$B$5)*100 | C41: % | D41: SUS-302
A43: Steering (SUS-601) — escopo reduzido, sem Ackermann/bump steer
A44: Steering Ratio (SR) | B44: 4.5 | C44: - | D44: SUS-601
A46: Pneu em série e ride rate (EDR-045) — K_T PROVISÓRIO: rigidez vertical do .tir TTC, não é o pneu do carro
A47: Rigidez vertical do pneu - dianteiro (K_T) | B47: 120312 | C47: N/m | D47: SUS-211
...

Sheet 07_KINEMATICS
A1: 07_KINEMATICS
A3: Status: PROVISÓRIO (estrutura pronta; valores abaixo NÃO vêm do OptimumKinematics ainda)
A4: Todos os campos desta aba são PLACEHOLDER até a Fase 2 (integração real com OptimumKinematics). Servem para a fórmula de Anti-Dive/Anti-Squat funcionar de ponta a ponta antes de existir dado real.
A6: Kinematic Operating Point (KOP) ativo
A7: KOP | B7: Ride Height Estático (RH) | C7: - | D7: -
A9: Instant Center — Vista Lateral (SUS-406) — usado por Anti-Dive/Anti-Squat
A10: Altura do IC lateral dianteiro (z_ICF) | B10: 0.2 | C10: m | D10: SUS-406-F
A11: Δx do IC lateral dianteiro ao contact patch (x_IC − x_CP; ISO: + = à frente) | B11: -2.5 | C11: m | D11: SUS-406-F
A12: Altura do IC lateral traseiro (z_ICR) | B12: 0.25 | C12: m | D12: SUS-406-R
A13: Δx do IC lateral traseiro ao centro da roda (x_IC − x_WC; ISO: + = à frente) | B13: 2 | C13: m | D13: SUS-406-R
A14: Altura do centro da roda traseira (ponto de reação do anti-squat) | B14: ='05_VEHICLE'!$B$17 | C14: m | D14: SUS-406-R
A15: Instant Center — Vista Frontal (SUS-403) — cross-check de RC (SUS-402) via Python
A16: SUS-402 (RC via interseção geométrica do IC frontal) foi formalizado e implementado em kinematics_model_V2_0.py (V2) - testado 11/11 (SUS-402 e SUS-406) com geometria sintética (DR-009). NÃO implementado em fórmula do Excel (complexidade de dupla interseção 2D não compensa em planilha). Os campos abaixo alimentariam esse script quando hardpoints reais existirem; hoje são só posição de referência.
A17: Y do IC frontal dianteiro | B17: 1.5 | C17: m | D17: SUS-403-F
A18: Z do IC frontal dianteiro | B18: 0.15 | C18: m | D18: SUS-403-F
A19: Y do IC frontal traseiro | B19: 1.8 | C19: m | D19: SUS-403-R
A20: Z do IC frontal traseiro | B20: 0.2 | C20: m | D20: SUS-403-R
A22: Camber Gain (SUS-404) — não alimenta nenhum cálculo de carga da V1, só REFERENCE
A23: Camber Gain dianteiro (dCamber/dz) | B23: -0.6 | C23: deg/mm | D23: SUS-404-F
A24: Camber Gain traseiro (dCamber/dz) | B24: -0.5 | C24: deg/mm | D24: SUS-404-R
A26: Toe Curve (SUS-405) — não alimenta nenhum cálculo de carga da V1, só REFERENCE
A27: Toe Gain dianteiro (dToe/dz) | B27: 0.05 | C27: deg/mm | D27: SUS-405-F
A28: Toe Gain traseiro (dToe/dz) | B28: 0.05 | C28: deg/mm | D28: SUS-405-R
A30: Curso de Suspensão Disponível — para checagem contra REQ-004 (>=50mm)
A31: Curso útil disponível - dianteiro (bump+rebound) | B31: 60 | C31: mm | D31: -
A32: Curso útil disponível - traseiro (bump+rebound) | B32: 65 | C32: mm | D32: -
A34: V2.0 — Resultados do solver cinemático (Python; cross-check, nunca REFERENCE)
A35: Origem: kinematics_model_V2_0.py -> kinematics_sweep_<canto>.csv (Data Contract V2.0, seção 6). Atualização manual até existir bridge (DR-008). Preencher SOMENTE com hardpoints reais (Status diferente de SYNTHETIC). Enquanto não houver, os campos ficam N/A. O Excel não recalcula cinemática (DR-009).
A36: Camber estático - dianteiro | B36: N/A | C36: deg | D36: SUS-407 | E36: sem hardpoints reais
A37: Camber estático - traseiro | B37: N/A | C37: deg | D37: SUS-407 | E37: sem hardpoints reais
A38: Camber gain (dγ/dz) - dianteiro | B38: N/A | C38: deg/mm | D38: SUS-407 | E38: sem hardpoints reais
A39: Camber gain (dγ/dz) - traseiro | B39: N/A | C39: deg/mm | D39: SUS-407 | E39: sem hardpoints reais
A40: Toe estático - dianteiro | B40: N/A | C40: deg | D40: SUS-408 | E40: sem hardpoints reais
A41: Toe estático - traseiro | B41: N/A | C41: deg | D41: SUS-408 | E41: sem hardpoints reais
A42: Bump steer (dδ/dz) - dianteiro | B42: N/A | C42: deg/mm | D42: SUS-408 | E42: sem hardpoints reais
A43: Bump steer (dδ/dz) - traseiro | B43: N/A | C43: deg/mm | D43: SUS-408 | E43: sem hardpoints reais
A44: Caster - dianteiro | B44: N/A | C44: deg | D44: SUS-410 | E44: sem hardpoints reais
A45: Caster - traseiro | B45: N/A | C45: deg | D45: SUS-410 | E45: sem hardpoints reais
A46: KPI - dianteiro | B46: N/A | C46: deg | D46: SUS-410 | E46: sem hardpoints reais
A47: KPI - traseiro | B47: N/A | C47: deg | D47: SUS-410 | E47: sem hardpoints reais
...

Sheet 08_VEHICLE_STATE
A1: 08_VEHICLE_STATE
A3: Estado do veículo (manobra)
A4: Aceleração longitudinal (a_x) | B4: -5 | C4: m/s^2 | D4: -
A5: Aceleração lateral (a_y) | B5: 11.772 | C5: m/s^2 | D5: -
A7: Aero (constante por Setup — SUS-701/702, sem F_aero(v) na V1)
A8: Downforce total | B8: 400 | C8: N | D8: SUS-701
A9: Aero Balance (fração dianteira) | B9: 0.45 | C9: - | D9: SUS-702

Sheet 09_LOADS
A1: 09_LOADS
A3: Carga Estática (SUS-101)
A4: Carga estática eixo dianteiro (W_f) | B4: ='05_VEHICLE'!$B$4*9.81*('05_VEHICLE'!$B$10/'05_VEHICLE'!$B$6) | C4: N | D4: SUS-101
A5: Carga estática eixo traseiro (W_r) | B5: ='05_VEHICLE'!$B$4*9.81*('05_VEHICLE'!$B$9/'05_VEHICLE'!$B$6) | C5: N | D5: SUS-101
A6: Fz estático FL | B6: ='09_LOADS'!$B$4/2 | C6: N | D6: SUS-101
A7: Fz estático FR | B7: ='09_LOADS'!$B$4/2 | C7: N | D7: SUS-101
A8: Fz estático RL | B8: ='09_LOADS'!$B$5/2 | C8: N | D8: SUS-101
A9: Fz estático RR | B9: ='09_LOADS'!$B$5/2 | C9: N | D9: SUS-101
A11: Transferência Longitudinal (SUS-102)
A12: dFz longitudinal - eixo dianteiro | B12: =-'05_VEHICLE'!$B$4*'08_VEHICLE_STATE'!$B$4*'05_VEHICLE'!$B$5/'05_VEHICLE'!$B$6 | C12: N | D12: SUS-102
A13: dFz longitudinal - eixo traseiro | B13: =+'05_VEHICLE'!$B$4*'08_VEHICLE_STATE'!$B$4*'05_VEHICLE'!$B$5/'05_VEHICLE'!$B$6 | C13: N | D13: SUS-102
A14: dFz longitudinal por canto - dianteira | B14: ='09_LOADS'!$B$12/2 | C14: N | D14: SUS-102
A15: dFz longitudinal por canto - traseira | B15: ='09_LOADS'!$B$13/2 | C15: N | D15: SUS-102
A17: Transferência Lateral — Milliken, três massas, com termo gravitacional (SUS-103)
A18: Altura do roll axis no CG suspenso (z_s, em a_s) | B18: ='06_SUSPENSION'!$B$14+('06_SUSPENSION'!$B$15-'06_SUSPENSION'!$B$14)*'05_VEHICLE'!$B$27/'05_VEHICLE'!$B$6 | C18: m | D18: -
A19: dFz lateral - eixo dianteiro | B19: =IF(ISNUMBER('09_LOADS'!$B$21),('06_SUSPENSION'!$B$22*'09_LOADS'!$B$21+'08_VEHICLE_STATE'!$B$5*('05_VEHICLE'!$B$25*'06_SUSPENSION'!$B$14+'05_VEHICLE'!$B$14*'05_VEHICLE'!$B$16))/'05_VEHICLE'!$B$7,"N/A") | C19: N | D19: SUS-103
A20: dFz lateral - eixo traseiro | B20: =IF(ISNUMBER('09_LOADS'!$B$21),('06_SUSPENSION'!$B$23*'09_LOADS'!$B$21+'08_VEHICLE_STATE'!$B$5*('05_VEHICLE'!$B$26*'06_SUSPENSION'!$B$15+'05_VEHICLE'!$B$15*'05_VEHICLE'!$B$17))/'05_VEHICLE'!$B$8,"N/A") | C20: N | D20: SUS-103
A21: Ângulo de rolagem φ = m_s·a_y·h2/(K_φF+K_φR − m_s·g·h2) (+ = para fora da curva) | B21: =IF('06_SUSPENSION'!$B$22+'06_SUSPENSION'!$B$23-'05_VEHICLE'!$B$23*9.81*('05_VEHICLE'!$B$24-'09_LOADS'!$B$18)<=0,"N/A - instabilidade de rolagem (m_s·g·h2 >= K_φ, Milliken p. 682)",'05_VEHICLE'!$B$23*'08_VEHICLE_STATE'!$B$5*('05_VEHICLE'!$B$24-'09_LOADS'!$B$18)/('06_SUSPENSION'!$B$22+'06_SUSPENSION'!$B$23-'05_VEHICLE'!$B$23*9.81*('05_VEHICLE'!$B$24-'09_LOADS'!$B$18))) | C21: rad | D21: SUS-103
A22: Aero por canto (SUS-701/702)
A23: Fz aero - eixo dianteiro | B23: ='08_VEHICLE_STATE'!$B$8*'08_VEHICLE_STATE'!$B$9 | C23: N | D23: -
A24: Fz aero - eixo traseiro | B24: ='08_VEHICLE_STATE'!$B$8*(1-'08_VEHICLE_STATE'!$B$9) | C24: N | D24: -
A25: Fz aero FL | B25: ='09_LOADS'!$B$23/2 | C25: N | D25: -
A26: Fz aero FR | B26: ='09_LOADS'!$B$23/2 | C26: N | D26: -
A27: Fz aero RL | B27: ='09_LOADS'!$B$24/2 | C27: N | D27: -
A28: Fz aero RR | B28: ='09_LOADS'!$B$24/2 | C28: N | D28: -
A30: Fz Combinado por Canto (SUS-104)
A31: Fz FL | B31: ='09_LOADS'!$B$6+'09_LOADS'!$B$14-'09_LOADS'!$B$19+'09_LOADS'!$B$25 | C31: N | D31: SUS-104
A32: Fz FR | B32: ='09_LOADS'!$B$7+'09_LOADS'!$B$14+'09_LOADS'!$B$19+'09_LOADS'!$B$26 | C32: N | D32: SUS-104
A33: Fz RL | B33: ='09_LOADS'!$B$8+'09_LOADS'!$B$15-'09_LOADS'!$B$20+'09_LOADS'!$B$27 | C33: N | D33: SUS-104
A34: Fz RR | B34: ='09_LOADS'!$B$9+'09_LOADS'!$B$15+'09_LOADS'!$B$20+'09_LOADS'!$B$28 | C34: N | D34: SUS-104

Sheet 10_TIRE
A1: 10_TIRE
A3: Aviso — DATASET PROVISÓRIO (dado de desenvolvimento): os coeficientes abaixo vêm de um .tir TTC recebido para permitir o desenvolvimento; NÃO correspondem necessariamente ao pneu que será usado. Nada nesta aba é medição ou resultado do carro (Guia: o workbook não apresenta μ próprio como medido).
A4: Dataset (metadados) — SUS-501/502/503, DR-011 e DR-013
A5: Arquivo do dataset | B5: Hoosier_R25B_13x7_TTC_provisional.tir
A6: Fonte / proveniência | B6: TTC via Stackpole (.tir); recebido em chat; PROVISÓRIO
A7: Formato do modelo | B7: PAC2002 (≈ MF 5.2), USE_MODE 4 (combinado), estacionário
A8: Tire REV (01_SETUP) | B8: ='01_SETUP'!$B$11
A9: Lado do arquivo (TYRESIDE) | B9: Right
A10: convention_status (sinais de α, κ, γ) | B10: USER_ASSERTED — dados do TTC (SAE); sinal de IA/camber NÃO confirmado
A11: Sistema de eixos do arquivo (declarado): SAE_CALSPAN ou ISO_TYDEX | B11: SAE_CALSPAN
A12: s_α (α_arquivo = s_α · α_ISO) | B12: =IF($B$11="SAE_CALSPAN",-1,IF($B$11="ISO_TYDEX",1,"N/A"))
A13: s_Fy (Fy_ISO = s_Fy · Fy_arquivo) | B13: =IF($B$11="SAE_CALSPAN",-1,IF($B$11="ISO_TYDEX",1,"N/A"))
A14: s_γ (γ_arquivo = s_γ · γ_projeto) — INFERÊNCIA no modo SAE | B14: =IF($B$11="SAE_CALSPAN",-1,IF($B$11="ISO_TYDEX",1,"N/A"))
A15: Nível do modelo (DEC-007) | B15: 2 — avaliação paramétrica dos coeficientes (sem fit próprio)
A16: Verificação das equações (V2.3) | B16: Fy0 confere com Seward eq. 5.5-5.13 (PAC'96/2002); combinado (Gxα, Gyκ, SVyκ) com Pacejka 2006 eq. 4.E50-4.E67; Ky com um único λFz0 (EDR-049). Reproduz o MFeval MF5.2. NÃO validado contra medição nem OptimumTire
A17: Dataset válido (IP = IP_NOM, PP* = 0, faixas coerentes, eixos declarados)? | B17: =IF(AND($B$95=$B$96,SUMPRODUCT(ABS($B$168:$B$175))=0,$B$88>$B$87,$B$86>0,ISNUMBER($B$12),ISNUMBER($B$13),ISNUMBER($B$14)),"OK","INVÁLIDO")
A19: Entradas por canto (FL, FR, RL, RR) e caso de verificação (VERIF) — α, γ, κ são DEMONSTRATIVOS
A20: Canto | B20: FL | C20: FR | D20: RL | E20: RR | F20: VERIF
A21: Lado da roda (L esquerda / R direita) | B21: L | C21: R | D21: L | E21: R | F21: R | G21: - | H21: SUS-501
A22: Fz (de 09_LOADS, SUS-104; VERIF: valor fixo) | B22: ='09_LOADS'!$B$31 | C22: ='09_LOADS'!$B$32 | D22: ='09_LOADS'!$B$33 | E22: ='09_LOADS'!$B$34 | F22: 700 | G22: N | H22: SUS-104
A23: Ângulo de deriva α (ISO 8855: + = velocidade p/ esquerda) | B23: -3 | C23: -3 | D23: -2 | E23: -2 | F23: 3 | G23: ° | H23: SUS-501
A24: Camber γ (projeto: + = topo para fora) | B24: -1.5 | C24: -1.5 | D24: -1 | E24: -1 | F24: 1.5 | G24: ° | H24: SUS-404
A25: Slip ratio κ (ISO: −1 = travada em frenagem) | B25: -0.05 | C25: -0.05 | D25: -0.03 | E25: -0.03 | F25: 0.05 | G25: - | H25: SUS-502
A26: Status do ponto de operação (faixa do dataset) | B26: =IF(NOT(AND(ISNUMBER(B$22),ISNUMBER(B$23),ISNUMBER(B$24),ISNUMBER(B$25))),"N/A - entrada ausente",IF($B$17<>"OK","N/A - dataset inválido",IF(B$22<=0,"N/A - Fz<=0 (liftoff)",IF(OR(B$22<$B$87,B$22>$B$88),"N/A - Fz fora da faixa",IF(OR(B$38<$B$89,B$38>$B$90),"N/A - α fora da faixa",IF(OR(B$39<$B$91,B$39>$B$92),"N/A - camber fora da faixa",IF(OR(B$25<$B$93,B$25>$B$94),"N/A - κ fora da faixa","OK"))))))) | C26: =IF(NOT(AND(ISNUMBER(C$22),ISNUMBER(C$23),ISNUMBER(C$24),ISNUMBER(C$25))),"N/A - entrada ausente",IF($B$17<>"OK","N/A - dataset inválido",IF(C$22<=0,"N/A - Fz<=0 (liftoff)",IF(OR(C$22<$B$87,C$22>$B$88),"N/A - Fz fora da faixa",IF(OR(C$38<$B$89,C$38>$B$90),"N/A - α fora da faixa",IF(OR(C$39<$B$91,C$39>$B$92),"N/A - camber fora da faixa",IF(OR(C$25<$B$93,C$25>$B$94),"N/A - κ fora da faixa","OK"))))))) | D26: =IF(NOT(AND(ISNUMBER(D$22),ISNUMBER(D$23),ISNUMBER(D$24),ISNUMBER(D$25))),"N/A - entrada ausente",IF($B$17<>"OK","N/A - dataset inválido",IF(D$22<=0,"N/A - Fz<=0 (liftoff)",IF(OR(D$22<$B$87,D$22>$B$88),"N/A - Fz fora da faixa",IF(OR(D$38<$B$89,D$38>$B$90),"N/A - α fora da faixa",IF(OR(D$39<$B$91,D$39>$B$92),"N/A - camber fora da faixa",IF(OR(D$25<$B$93,D$25>$B$94),"N/A - κ fora da faixa","OK"))))))) | E26: =IF(NOT(AND(ISNUMBER(E$22),ISNUMBER(E$23),ISNUMBER(E$24),ISNUMBER(E$25))),"N/A - entrada ausente",IF($B$17<>"OK","N/A - dataset inválido",IF(E$22<=0,"N/A - Fz<=0 (liftoff)",IF(OR(E$22<$B$87,E$22>$B$88),"N/A - Fz fora da faixa",IF(OR(E$38<$B$89,E$38>$B$90),"N/A - α fora da faixa",IF(OR(E$39<$B$91,E$39>$B$92),"N/A - camber fora da faixa",IF(OR(E$25<$B$93,E$25>$B$94),"N/A - κ fora da faixa","OK"))))))) | F26: =IF(NOT(AND(ISNUMBER(F$22),ISNUMBER(F$23),ISNUMBER(F$24),ISNUMBER(F$25))),"N/A - entrada ausente",IF($B$17<>"OK","N/A - dataset inválido",IF(F$22<=0,"N/A - Fz<=0 (liftoff)",IF(OR(F$22<$B$87,F$22>$B$88),"N/A - Fz fora da faixa",IF(OR(F$38<$B$89,F$38>$B$90),"N/A - α fora da faixa",IF(OR(F$39<$B$91,F$39>$B$92),"N/A - camber fora da faixa",IF(OR(F$25<$B$93,F$25>$B$94),"N/A - κ fora da faixa","OK"))))))) | I26: Sem extrapolação: fora da faixa do dataset (FZMIN/FZMAX, α, γ, κ) o resultado é N/A, não um valor extrapolado. Fz≤0 = perda de contato.
A28: Resultados — SUS-501 (Fy), SUS-502 (Fx), SUS-503 (μ efetivo) — convenção do PROJETO
A29: Fx combinado (SUS-502) = Gxα·Fx0 | B29: =IF(B$26<>"OK","N/A",B$74*B$52) | C29: =IF(C$26<>"OK","N/A",C$74*C$52) | D29: =IF(D$26<>"OK","N/A",D$74*D$52) | E29: =IF(E$26<>"OK","N/A",E$74*E$52) | F29: =IF(F$26<>"OK","N/A",F$74*F$52) | G29: N | H29: SUS-502 | I29: Referencial do dataset (idêntico nos dois lados). + = força para frente (κ>0).
A30: Fy combinado (SUS-501), convenção do projeto | B30: =IF(B$26<>"OK","N/A",B$35*$B$13*(B$81*B$65+B$83)) | C30: =IF(C$26<>"OK","N/A",C$35*$B$13*(C$81*C$65+C$83)) | D30: =IF(D$26<>"OK","N/A",D$35*$B$13*(D$81*D$65+D$83)) | E30: =IF(E$26<>"OK","N/A",E$35*$B$13*(E$81*E$65+E$83)) | F30: =IF(F$26<>"OK","N/A",F$35*$B$13*(F$81*F$65+F$83)) | G30: N | H30: SUS-501 | I30: Fy_ISO = espelhamento · s_Fy · Fy_arquivo. Em curva à esquerda (α<0 ISO) Fy>0 = para a esquerda.
A31: μ efetivo (SUS-503) = √(Fx²+Fy²)/Fz | B31: =IF(B$26<>"OK","N/A",SQRT(B$29^2+B$30^2)/B$22) | C31: =IF(C$26<>"OK","N/A",SQRT(C$29^2+C$30^2)/C$22) | D31: =IF(D$26<>"OK","N/A",SQRT(D$29^2+D$30^2)/D$22) | E31: =IF(E$26<>"OK","N/A",SQRT(E$29^2+E$30^2)/E$22) | F31: =IF(F$26<>"OK","N/A",SQRT(F$29^2+F$30^2)/F$22) | G31: - | H31: SUS-503 | I31: μ DERIVADO do dataset provisório — não é medição da equipe nem do carro.
A32: Fy no referencial do arquivo (pneu Right, sem conversão) | B32: =IF(B$26<>"OK","N/A",B$81*B$65+B$83) | C32: =IF(C$26<>"OK","N/A",C$81*C$65+C$83) | D32: =IF(D$26<>"OK","N/A",D$81*D$65+D$83) | E32: =IF(E$26<>"OK","N/A",E$81*E$65+E$83) | F32: =IF(F$26<>"OK","N/A",F$81*F$65+F$83) | G32: N | H32: SUS-501
A34: Cálculo — conversões e carga normalizada
A35: Fator de espelhamento do lado (L=−1, R=+1) | B35: =IF(B$21="L",-1,1) | C35: =IF(C$21="L",-1,1) | D35: =IF(D$21="L",-1,1) | E35: =IF(E$21="L",-1,1) | F35: =IF(F$21="L",-1,1) | G35: - | H35: H4
A36: α [rad] | B36: =IF(ISNUMBER(B$23),RADIANS(B$23),"N/A") | C36: =IF(ISNUMBER(C$23),RADIANS(C$23),"N/A") | D36: =IF(ISNUMBER(D$23),RADIANS(D$23),"N/A") | E36: =IF(ISNUMBER(E$23),RADIANS(E$23),"N/A") | F36: =IF(ISNUMBER(F$23),RADIANS(F$23),"N/A") | G36: rad | H36: SUS-501
A37: γ [rad] | B37: =IF(ISNUMBER(B$24),RADIANS(B$24),"N/A") | C37: =IF(ISNUMBER(C$24),RADIANS(C$24),"N/A") | D37: =IF(ISNUMBER(D$24),RADIANS(D$24),"N/A") | E37: =IF(ISNUMBER(E$24),RADIANS(E$24),"N/A") | F37: =IF(ISNUMBER(F$24),RADIANS(F$24),"N/A") | G37: rad | H37: SUS-501
A38: α no referencial do arquivo [rad] = s_α · espelhamento · α | B38: =IF(AND(ISNUMBER(B$36),ISNUMBER($B$12)),$B$12*B$35*B$36,"N/A") | C38: =IF(AND(ISNUMBER(C$36),ISNUMBER($B$12)),$B$12*C$35*C$36,"N/A") | D38: =IF(AND(ISNUMBER(D$36),ISNUMBER($B$12)),$B$12*D$35*D$36,"N/A") | E38: =IF(AND(ISNUMBER(E$36),ISNUMBER($B$12)),$B$12*E$35*E$36,"N/A") | F38: =IF(AND(ISNUMBER(F$36),ISNUMBER($B$12)),$B$12*F$35*F$36,"N/A") | G38: rad | H38: H3b/H4
A39: γ no referencial do arquivo [rad] = s_γ · γ | B39: =IF(AND(ISNUMBER(B$37),ISNUMBER($B$14)),$B$14*B$37,"N/A") | C39: =IF(AND(ISNUMBER(C$37),ISNUMBER($B$14)),$B$14*C$37,"N/A") | D39: =IF(AND(ISNUMBER(D$37),ISNUMBER($B$14)),$B$14*D$37,"N/A") | E39: =IF(AND(ISNUMBER(E$37),ISNUMBER($B$14)),$B$14*E$37,"N/A") | F39: =IF(AND(ISNUMBER(F$37),ISNUMBER($B$14)),$B$14*F$37,"N/A") | G39: rad | H39: H3b
A40: dfz = (Fz − LFZO·FNOMIN)/(LFZO·FNOMIN) | B40: =IF(B$26<>"OK","N/A",(B$22-$B$97*$B$86)/($B$97*$B$86)) | C40: =IF(C$26<>"OK","N/A",(C$22-$B$97*$B$86)/($B$97*$B$86)) | D40: =IF(D$26<>"OK","N/A",(D$22-$B$97*$B$86)/($B$97*$B$86)) | E40: =IF(E$26<>"OK","N/A",(E$22-$B$97*$B$86)/($B$97*$B$86)) | F40: =IF(F$26<>"OK","N/A",(F$22-$B$97*$B$86)/($B$97*$B$86)) | G40: - | H40: SUS-501
A42: Cálculo — Fx puro (Fx0), forma PAC2002/MF 5.2
A43: SHx = (PHX1+PHX2·dfz)·LHX | B43: =IF(B$26<>"OK","N/A",($B$126+$B$127*B$40)*$B$102) | C43: =IF(C$26<>"OK","N/A",($B$126+$B$127*C$40)*$B$102) | D43: =IF(D$26<>"OK","N/A",($B$126+$B$127*D$40)*$B$102) | E43: =IF(E$26<>"OK","N/A",($B$126+$B$127*E$40)*$B$102) | F43: =IF(F$26<>"OK","N/A",($B$126+$B$127*F$40)*$B$102) | G43: - | H43: SUS-502
A44: κx = κ + SHx | B44: =IF(B$26<>"OK","N/A",B$25+B$43) | C44: =IF(C$26<>"OK","N/A",C$25+C$43) | D44: =IF(D$26<>"OK","N/A",D$25+D$43) | E44: =IF(E$26<>"OK","N/A",E$25+E$43) | F44: =IF(F$26<>"OK","N/A",F$25+F$43) | G44: - | H44: SUS-502
A45: Cx = PCX1·LCX | B45: =IF(B$26<>"OK","N/A",$B$115*$B$98) | C45: =IF(C$26<>"OK","N/A",$B$115*$B$98) | D45: =IF(D$26<>"OK","N/A",$B$115*$B$98) | E45: =IF(E$26<>"OK","N/A",$B$115*$B$98) | F45: =IF(F$26<>"OK","N/A",$B$115*$B$98) | G45: - | H45: SUS-502
...

Sheet 11_DESIGN
A1: 11_DESIGN — Design Mode
A3: Target de frequência (TARGET-XXX)
A4: Frequência-alvo dianteira | B4: 2.5 | C4: Hz | D4: TARGET-001
A5: Frequência-alvo traseira | B5: 2.7 | C5: Hz | D5: TARGET-002
A7: Rigidez necessária (equação reversa, SUS-205/212/202; pneu em série)
A8: Wheel Rate necessário - dianteira (K_R alvo -> K_W = K_R·K_T/(K_T − K_R)) | B8: =(2*PI()*'11_DESIGN'!$B$4)^2*'06_SUSPENSION'!$B$28*'06_SUSPENSION'!$B$47/('06_SUSPENSION'!$B$47-(2*PI()*'11_DESIGN'!$B$4)^2*'06_SUSPENSION'!$B$28) | C8: N/m | D8: SUS-205
A9: Wheel Rate necessário - traseira (K_R alvo -> K_W = K_R·K_T/(K_T − K_R)) | B9: =(2*PI()*'11_DESIGN'!$B$5)^2*'06_SUSPENSION'!$B$29*'06_SUSPENSION'!$B$48/('06_SUSPENSION'!$B$48-(2*PI()*'11_DESIGN'!$B$5)^2*'06_SUSPENSION'!$B$29) | C9: N/m | D9: SUS-205
A10: Spring Rate necessário - dianteira | B10: ='11_DESIGN'!$B$8*'06_SUSPENSION'!$B$6^2 | C10: N/m | D10: SUS-202
A11: Spring Rate necessário - traseira | B11: ='11_DESIGN'!$B$9*'06_SUSPENSION'!$B$7^2 | C11: N/m | D11: SUS-202
A13: Comparação com o Spring Rate atual (06_SUSPENSION)
A14: Diferença dianteira (necessário - atual) | B14: ='11_DESIGN'!$B$10-'06_SUSPENSION'!$B$4 | C14: N/m | D14: -
A15: Diferença traseira (necessário - atual) | B15: ='11_DESIGN'!$B$11-'06_SUSPENSION'!$B$5 | C15: N/m | D15: -
A17: Target de Roll Stiffness Distribution (equação reversa, SUS-208 — DRAFT, ver Engineering Standard)
A18: lambda_f alvo | B18: 0.55 | C18: - | D18: TARGET-003
A19: Roll Stiffness dianteira necessária (K_phiF total) | B19: =('11_DESIGN'!$B$18/(1-'11_DESIGN'!$B$18))*'06_SUSPENSION'!$B$23 | C19: N*m/rad | D19: SUS-208
A20: K_ARB dianteiro necessário (com o pneu em série) | B20: ='11_DESIGN'!$B$19*'06_SUSPENSION'!$B$51/('06_SUSPENSION'!$B$51-'11_DESIGN'!$B$19)-'06_SUSPENSION'!$B$20 | C20: N*m/rad | D20: SUS-206
A21: Diferença K_ARB dianteiro (necessário - atual) | B21: ='11_DESIGN'!$B$20-'06_SUSPENSION'!$B$10 | C21: N*m/rad | D21: -

Sheet 12_COMPARISON
A1: 12_COMPARISON
A3: Comparação entre Setups/alternativas — vazio até existir mais de um Setup real
A4: Estrutura reservada. Nao ha ainda um segundo Setup real do Design Case para comparar contra o Baseline.
A5: Preencher quando houver pelo menos duas configuracoes concretas a comparar (evita aba decorativa vazia).

Sheet 13_VALIDATION
A1: 13_VALIDATION
A3: Self-checks de conservação (equivalentes a TC-004 / TC-005 / lambda)
A4: TC-004: Sum(Fz) - (W+Faero) [deve ser ~0] | B4: ='09_LOADS'!$B$31+'09_LOADS'!$B$32+'09_LOADS'!$B$33+'09_LOADS'!$B$34-('05_VEHICLE'!$B$4*9.81+'08_VEHICLE_STATE'!$B$8) | C4: N | D4: TC-004
A5: Status TC-004 | B5: =IF(ABS('13_VALIDATION'!$B$4)<0.01,"PASS","FAIL") | C5: - | D5: -
A6: TC-005: t_F*dFzF + t_R*dFzR - m*ay*h_CG - m_s*g*h2*φ [deve ser ~0] | B6: ='05_VEHICLE'!$B$7*'09_LOADS'!$B$19+'05_VEHICLE'!$B$8*'09_LOADS'!$B$20-'05_VEHICLE'!$B$4*'08_VEHICLE_STATE'!$B$5*'05_VEHICLE'!$B$5-'05_VEHICLE'!$B$23*9.81*('05_VEHICLE'!$B$24-'09_LOADS'!$B$18)*'09_LOADS'!$B$21 | C6: N*m | D6: TC-005
A7: Status TC-005 | B7: =IF(ABS('13_VALIDATION'!$B$6)<0.01,"PASS","FAIL") | C7: - | D7: -
A8: Checagem: lambda_f + lambda_r = 1 | B8: ='06_SUSPENSION'!$B$24+'06_SUSPENSION'!$B$25 | C8: - | D8: SUS-208
A10: Plausibilidade — perda de contato (Fz < 0 invalida o modelo linear, ver SUS-104)
A11: Fz FL >= 0 ? | B11: =IF('09_LOADS'!$B$31>=0,"OK","WARNING: perda de contato") | C11: - | D11: -
A12: Fz FR >= 0 ? | B12: =IF('09_LOADS'!$B$32>=0,"OK","WARNING: perda de contato") | C12: - | D12: -
A13: Fz RL >= 0 ? | B13: =IF('09_LOADS'!$B$33>=0,"OK","WARNING: perda de contato") | C13: - | D13: -
A14: Fz RR >= 0 ? | B14: =IF('09_LOADS'!$B$34>=0,"OK","WARNING: perda de contato") | C14: - | D14: -
A16: Checagem contra Requirements (02_REQUIREMENTS)
A17: tan(ângulo de tombamento) — usa a MENOR bitola (pior caso) | B17: =(MIN('05_VEHICLE'!$B$7,'05_VEHICLE'!$B$8)/2)/'05_VEHICLE'!$B$5 | C17: - | D17: REQ-003
A18: Ângulo de tombamento (graus) | B18: =DEGREES(ATAN('13_VALIDATION'!$B$17)) | C18: deg | D18: REQ-003
A19: Status REQ-003 (Tilt Test, mínimo 60°) | B19: =IF('13_VALIDATION'!$B$18>=60,"PASS","FAIL - risco de reprovacao no Tilt Test") | C19: - | D19: REQ-003
A21: Status REQ-004 (curso dianteiro, mínimo 50mm) | B21: =IF('07_KINEMATICS'!$B$31>=50,"PASS","FAIL") | C21: - | D21: REQ-004
A22: Status REQ-004 (curso traseiro, mínimo 50mm) | B22: =IF('07_KINEMATICS'!$B$32>=50,"PASS","FAIL") | C22: - | D22: REQ-004
A24: Referência — resultado do piloto Python (atualizar manualmente até o bridge existir)
A25: 16/16 Test Cases PASS em suspension_model_V2_0.py / test_suspension_model_V2_0.py (ver Engineering Standard V2.0, Log de Validação)
A26: Piloto de referência: MR=0.8, Ks=100 N/mm, ms=50 kg, pneu rígido -> fn=8.897 Hz (verificado)
A28: Checagem adicional de requisitos (V2.1) — REQ-001 e REQ-002 (02_REQUIREMENTS; Rulebook V.1.2 e V.1.3.2)
A29: Wheelbase (mm) — a partir de 05_VEHICLE!B6 | B29: =IF(ISNUMBER('05_VEHICLE'!$B$6),'05_VEHICLE'!$B$6*1000,"N/A") | C29: mm | D29: REQ-001
A30: Status REQ-001 (wheelbase mínimo 1525 mm) | B30: =IF(ISNUMBER($B$29),IF($B$29>=1525,"PASS","FAIL - wheelbase abaixo do mínimo (V.1.2)"),"N/A - dado ausente") | C30: - | D30: REQ-001
A31: Razão entre bitolas (menor/maior) — 05_VEHICLE!B7 e B8 | B31: =IF(AND(ISNUMBER('05_VEHICLE'!$B$7),ISNUMBER('05_VEHICLE'!$B$8)),MIN('05_VEHICLE'!$B$7,'05_VEHICLE'!$B$8)/MAX('05_VEHICLE'!$B$7,'05_VEHICLE'!$B$8),"N/A") | C31: - | D31: REQ-002
A32: Status REQ-002 (razão de bitolas mínima 0,75) | B32: =IF(ISNUMBER($B$31),IF($B$31>=0.75,"PASS","FAIL - razão de bitolas abaixo de 0,75 (V.1.3.2)"),"N/A - dado ausente") | C32: - | D32: REQ-002
A33: Dados de entrada: E05 Key Parameters (comentários de 05_VEHICLE B6/B7/B8) — especificação, não medição independente. Estado de validação: NOT_VALIDATED (sem medição física).
A35: Pneu (V2.2) — SUS-501/502/503; dataset TTC PROVISÓRIO (10_TIRE, DR-013). Sem comparação com OptimumTire/TTC: Validation = NOT_VALIDATED
A36: Dataset de pneu: validade formal (IP=IP_NOM, PP*=0, faixas) | B36: ='10_TIRE'!$B$17 | C36: - | D36: SUS-501
A37: Referência Python — Fx do caso VERIF [N] (resultado de código) | B37: 1526.9251 | C37: N | D37: SUS-502
A38: Referência Python — Fy do caso VERIF [N] (resultado de código) | B38: -1131.8643 | C38: N | D38: SUS-501
A39: Referência Python — μ_eff do caso VERIF (resultado de código) | B39: 2.7152694 | C39: - | D39: SUS-503
A40: Status: Fx Excel (10_TIRE!F) vs Python — tol. numérica 1e-6 relativa | B40: =IF(ISNUMBER('10_TIRE'!$F$29),IF(ABS('10_TIRE'!$F$29-$B$37)<=0.000001*MAX(1,ABS($B$37)),"PASS","FAIL - Excel diverge do Python"),"N/A - caso VERIF fora da faixa ou dataset inválido") | C40: - | D40: SUS-502
A41: Status: Fy Excel vs Python — tol. numérica 1e-6 relativa | B41: =IF(ISNUMBER('10_TIRE'!$F$30),IF(ABS('10_TIRE'!$F$30-$B$38)<=0.000001*MAX(1,ABS($B$38)),"PASS","FAIL - Excel diverge do Python"),"N/A - caso VERIF fora da faixa ou dataset inválido") | C41: - | D41: SUS-501
A42: Status: μ_eff Excel vs Python — tol. numérica 1e-6 relativa | B42: =IF(ISNUMBER('10_TIRE'!$F$31),IF(ABS('10_TIRE'!$F$31-$B$39)<=0.000001*MAX(1,ABS($B$39)),"PASS","FAIL - Excel diverge do Python"),"N/A - caso VERIF fora da faixa ou dataset inválido") | C42: - | D42: SUS-503
A43: Cantos com resultado de pneu válido (de 4, 10_TIRE) | B43: =COUNTIF('10_TIRE'!$B$26:$E$26,"OK") | C43: - | D43: SUS-501
A44: Tolerâncias: numérica = 1e-6 relativa (mesmas equações em dupla implementação; não há referência externa); de engenharia = NÃO DEFINIDA (exige OptimumTire/TTC). PASS aqui = Excel reproduz Python, NÃO validação física. Python: 34/34 testes + 5/5 contra 2 códigos de terceiros (Racer CalcMF52; MFeval MF5.2) — concordância de TRANSCRIÇÃO, não validação física nem contra o livro.

Sheet 14_DASHBOARD
A1: 14_DASHBOARD
A3: Setup ativo
A4: Setup | B4: ='01_SETUP'!$B$4&" - "&'01_SETUP'!$B$5 | C4: - | D4: -
A6: Fz por canto (N)
A7: Fz FL | B7: ='09_LOADS'!$B$31 | C7: N | D7: SUS-104
A8: Fz FR | B8: ='09_LOADS'!$B$32 | C8: N | D8: SUS-104
A9: Fz RL | B9: ='09_LOADS'!$B$33 | C9: N | D9: SUS-104
A10: Fz RR | B10: ='09_LOADS'!$B$34 | C10: N | D10: SUS-104
A12: Rigidez e Frequência
A13: Wheel Rate dianteiro | B13: ='06_SUSPENSION'!$B$18 | C13: N/m | D13: SUS-202
A14: Wheel Rate traseiro | B14: ='06_SUSPENSION'!$B$19 | C14: N/m | D14: SUS-202
A15: Frequência Natural dianteira | B15: ='06_SUSPENSION'!$B$32 | C15: Hz | D15: SUS-205
A16: Frequência Natural traseira | B16: ='06_SUSPENSION'!$B$33 | C16: Hz | D16: SUS-205
A17: Distribuição de rigidez dianteira | B17: ='06_SUSPENSION'!$B$24 | C17: - | D17: SUS-208
A19: Status de Validação
A20: TC-004 (conservação de carga) | B20: ='13_VALIDATION'!$B$5 | C20: - | D20: -
A21: TC-005 (conservação de momento lateral) | B21: ='13_VALIDATION'!$B$7 | C21: - | D21: -
A22: REQ-003 (Tilt Test) | B22: ='13_VALIDATION'!$B$19 | C22: - | D22: -
A23: REQ-004 (curso dianteiro) | B23: ='13_VALIDATION'!$B$21 | C23: - | D23: -
A24: REQ-004 (curso traseiro) | B24: ='13_VALIDATION'!$B$22 | C24: - | D24: -
A26: Governança — Requirements / Targets / Decisions
A27: Requirements registrados | B27: =COUNTIF('02_REQUIREMENTS'!A:A,"REQ-*") | C27: - | D27: -
A28: Targets registrados | B28: =COUNTIF('03_TARGETS'!A:A,"TARGET-*") | C28: - | D28: -
A29: Targets em OPEN (sem valor real definido) | B29: =COUNTIF('03_TARGETS'!D:D,"OPEN") | C29: - | D29: -
A30: Decision Records registrados | B30: =COUNTIF('04_DECISION_REGISTER'!A:A,"DR-*") | C30: - | D30: -
A32: Pneu — dataset TTC PROVISÓRIO (não é o pneu do carro; μ derivado do dataset, não medido)
A33: Dataset de pneu (validade formal) | B33: ='10_TIRE'!$B$17 | C33: - | D33: SUS-501
A34: μ efetivo FL (demonstrativo) | B34: ='10_TIRE'!$B$31 | C34: - | D34: SUS-503
A35: μ efetivo FR (demonstrativo) | B35: ='10_TIRE'!$C$31 | C35: - | D35: SUS-503
A36: μ efetivo RL (demonstrativo) | B36: ='10_TIRE'!$D$31 | C36: - | D36: SUS-503
A37: μ efetivo RR (demonstrativo) | B37: ='10_TIRE'!$E$31 | C37: - | D37: SUS-503
A38: Convenção de sinais do pneu | B38: SAE→ISO (declarada); camber não confirmado | C38: - | D38: DR-013

Sheet 15_CHANGELOG
A1: 15_CHANGELOG
A3: Data | B3: Mudança | C3: Motivo
A4: 2026-09 | B4: Migracao da arquitetura de 9 para 16 abas (00_README...15_CHANGELOG) | C4: Sistema evoluiu de 'planilha de suspensao' para sistema de engenharia/memoria institucional da Mecanica
A5: 2026-09 | B5: Abas renomeadas (02_VEHICLE->05_VEHICLE, 03_SUSPENSION->06_SUSPENSION, etc.) via rename nativo do Excel | C5: Evitar reescrita manual de formulas - Excel atualiza referencias automaticamente ao renomear aba
A6: 2026-09 | B6: SUS-103 (Milliken two-spring) cross-referenciado contra Chalmers/Sampo | C6: Transcricao conferida termo a termo contra fonte externa publicada - identica, sem divergencia
A7: 2026-09 | B7: Wheel Rate do T09 corrigido de 21950 N/m (ambos os eixos) para 16112.23 F / 18418.2 R N/m | C7: Valor antigo vinha do spec sheet resumido (impreciso); planilha de calculo detalhada do T09 e mais confiavel
A8: 2026-09 | B8: Natural Frequency reclassificada de NOT_VALIDATED para PASS no T09 Reference Case | C8: Massa suspensa real do T09 (nao a nao-suspensa) e suficiente para a formula SUS-205; erro de entendimento anterior corrigido
A9: 2026-10 | B9: Decision Register consolidado: mantidas DR-001 a DR-009 da planilha (mais completas: Why/Constraints/Owner); adicionadas colunas Status e Origem; incluidas DR-010 (Design Mode explicito) e DR-011 (Tire como REFERENCE), vindas so do Guide. | C9: Planilha e Guide tinham versoes diferentes. Guide DR-008 (Tire) renumerado para DR-011 porque DR-008 da planilha (sem bridge Python-Excel) e outra decisao; Guide DR-009 ("solver interno nao e V1") tratado como a mesma decisao da DR-009 da planilha (Python-only, inicio da V2). Guide a alinhar depois.
A10: 2026-10 | B10: V1.0: versionamento dos artefatos (Standard, Arquitetura, Data Contract, suspension_model, kinematics_model e testes, planilha). README: versao V1.0 e correcao do aviso de Anti-dive/squat (ja implementados com placeholders); 07_KINEMATICS: 11/11; referencias de arquivo atualizadas para *_V1_0. | C10: Regra de versao: V1.0 -> V1.1 a cada pequena implementacao. Detalhes e divergencias abertas em registro-de-versoes-V1.0.md. Nenhuma formula foi alterada.
A11: 2026-10 | B11: V2.0: Kinematics (solver 3D + schema de hardpoints, Python), validacoes de entrada e aviso Fz<0 (Python). Planilha: 07_KINEMATICS ganha blocos de resultados do solver (N/A) e schema; DR-012; README/Setup atualizados. Nenhuma formula alterada. | C11: Resultados do solver sao cross-check e so entram na planilha com hardpoints reais. As propostas (IC lateral cinematico, %AD com sinal) NAO foram aplicadas as formulas de 06_SUSPENSION. Detalhes em registro-de-versoes-V2.0.md.
A12: 2026-10 | B12: V2.1 PARCIAL: 13_VALIDATION ganha REQ-001 (wheelbase >= 1525 mm) e REQ-002 (razao de bitolas >= 0,75), linhas 28-33; comentario de proveniencia em REQ-003 (B19); README e nota em 04. | C12: Somente adicoes: nenhuma das 84 formulas anteriores foi alterada. REQ-004 e demais resultados dependentes de placeholders NAO foram alterados (aguardam a Decisao A, EDR-025). Mapa de dependencias: placeholder-dependency-map-V2.1.csv.
A13: 2026-10 | B13: V2.2: 10_TIRE implementada (SUS-501 Fy, SUS-502 Fx, SUS-503 mu efetivo; PAC2002/MF 5.2 nivel 2, combinado) a partir de .tir TTC PROVISORIO; entradas por canto (Fz de 09_LOADS; alpha/gamma/kappa demonstrativos), faixa do dataset com N/A, caso VERIF. 13_VALIDATION linhas 35-44; 14_DASHBOARD linhas 32-38; 04_DECISION_REGISTER DR-013 (e texto de DR-011 E15); 01_SETUP Tire REV; README. Python: tire_model_V2_2.py + test_tire_model_V2_2.py. | C13: Pedido do usuario com dataset TTC para desenvolvimento. Somente adicoes + substituicao da aba 10_TIRE: as 88 formulas anteriores nao foram alteradas. Impacto: nenhum resultado existente muda. Validation: Python 34/34 (mutacao 17/17); Excel x Python (test_workbook_V2_2.py). NOT_VALIDATED fisicamente (sem OptimumTire). Revision: T-REV-A. Pendentes: confirmar convencao de sinais e espelhamento; dataset real; EDR-025/035/036; fichas SUS-501..503 do Standard devem refletir nivel 2 e convencao. Autor: nao registrado.
A14: 2026-10 | B14: V2.3: verificacao das equacoes do pneu contra 2 codigos de terceiros (Racer CalcMF52; MFeval ramo MF5.2) em 3000 pontos (dif <= 3,4e-4 N); novo metadado em 10_TIRE; texto de DR-013, 13_VALIDATION l.44 e README ajustados. Nenhuma formula alterada em relacao a V2.2. | C14: Pedido do usuario: encontrar fonte primaria e validar as equacoes. Fonte primaria (livro) nao acessivel; usadas fontes de terceiros. Impacto: apenas texto/metadado. Validation: test_tire_oracles_V2_2.py 5/5; Excel x Python mantido (test_workbook). Pendente: livro (Pacejka), OptimumTire e medicao. Revision: T-REV-A. Autor: nao registrado.
... A16: 2026-10 | B16: V2.5: revisao metodologica contra Milliken (RCVD), Gillespie, Seward e Pacejka. Pneu em serie na frequencia natural e na rigidez de rolagem (K_T provisorio do .tir; 06_SUSPENSION l.46-52, B22/B23, B32/B33; 11_DESIGN B8/B9/B20); SUS-103 com termo gravitacional e CG suspenso em a_s (09_LOADS B18-B21; 13_VALIDATION B6); massa suspensa por eixo (05_VEHICLE l.25-27; 06 B28/B29); anti-dive/anti-squat com sinal e ponto de reacao do carro (freio no cubo, motor no chassi; 06 B39-B41, 07 B11/B13/B14); Ky com um lambda_Fz0 (10_TIRE). | C16: Pedido do usuario (2026-10-19): seguir a literatura, principalmente o Milliken. EDR-045 a EDR-049. Registro celula a celula: docs/registro-de-versoes-V2_5.md. Validation: suspensao 54/54 (inclui exemplos da Milliken p. 683, p. 592, Tab. 16.3, Seward 4.1, Gillespie 5-8), Excel x Python (test_workbook e test_workbook_suspensao). NOT_VALIDATED fisicamente. Autor: nao registrado.
