Workbook

Sheet 00_README
A1: FSAE EV — Suspension Sizing Tool | Fase 1
A3: Versão do workbook: V2.1 PARCIAL (Gates 1-2 + atividades independentes; decisões A/B/C pendentes) | Status: DRAFT — cross-check, ainda NÃO REFERENCE-validated
A5: O que este workbook é (e o que não é)
A6: Este workbook implementa, em fórmulas nativas do Excel, as mesmas equações do Engineering Standard V2.0
A7: (SUS-001 a SUS-104, SUS-201/202/205/206/207/208, SUS-701/702), já verificadas no piloto Python
A8: (suspension_model_V2_0.py + test_suspension_model_V2_0.py, 16/16 Test Cases PASS).
A10: Isso NÃO substitui o Python como motor de referência. O Data Contract V2.0 continua definindo o fluxo
A11: Excel -> input.json -> Python -> results.json -> Excel para quando o bridge automático existir (Fase 2+).
A12: Até lá, este Excel é uma segunda implementação independente das MESMAS equações, útil para uso diário
A13: e como cross-check contra o Python — igual ao que já fazemos com RC/MR (REFERENCE vs. MODEL/CHECK).
A15: Legenda de cores
A16: ■ Azul | B16: INPUT — editável pelo usuário
A17: ■ Verde-teal | B17: REFERENCE — vem do CAD/hardpoints (digitado manualmente até a Fase 2 ter Power Query)
A18: ■ Laranja + fundo | B18: PROVISÓRIO — normalmente viria do OptimumKinematics (Fase 2); input manual temporário
A19: ■ Preto + fundo cinza | B19: CALCULATED — fórmula, não editar
A20: ■ Amarelo | B20: Hipótese-chave / célula de atenção
A22: Convenções congeladas (Engineering Standard, seção 4 e 17)
A23: • Sistema de coordenadas: ISO 8855 — X positivo para frente, Y positivo para esquerda, Z positivo para cima.
A24: • Pitch positivo = nariz descendo. Roll positivo = lado esquerdo sobe. Yaw positivo = anti-horário visto de cima.
A25: • Motion Ratio = deslocamento da roda / deslocamento da mola (MR [wheel/spring]).
A26: • Camber positivo = topo da roda para fora. Toe positivo = toe-out.
A27: • a_x positivo = aceleração para frente (transfere carga para trás). a_y positivo = para a esquerda (lado direito ganha carga).
A28: • SUS-000 (referência de solo): todas as alturas (h_CG, h_s, h_uF, h_uR, RC) são medidas a partir do solo, não da origem do CAD.
A30: Limitações conhecidas da V1.0 (declaradas, não escondidas)
A31: • Quase-estático: sem dinâmica transiente, sem modelo de amortecedor.
A32: • RC tratado como ponto fixo no ride height estático — migração de RC durante rolagem não modelada.
A33: • Aero fixo por Setup (sem F_aero(v)) — decisão congelada para V1.
A34: • Anti-dive/Anti-squat (SUS-301/302) estão implementados em 06_SUSPENSION, mas com FB_f, TF_r e Instant Center PLACEHOLDER (07_KINEMATICS) — não são valores reais do carro; a linha geométrica (contact patch vs. wheel center) ainda depende da configuração real de freio/trem de força. V2.0: o método de IC lateral e a forma sem sinal de tan(φ) usados nestas fórmulas são os da V1 (Standard V2.0, notas de SUS-406/301/302: mal condicionado e sem sinal físico); os valores seguem PLACEHOLDER e não representam o carro.
... A36: • Modelo linear de Fz por canto só é válido enquanto Fz >= 0 — resultado negativo indica perda de contato do pneu e extrapola o modelo (ver 13_VALIDATION).

Sheet 01_SETUP
A1: 01_SETUP
A3: Setup ativo
A4: Setup ID | B4: S-001
A5: Nome do Setup | B5: Baseline
A6: Notas | B6: Setup de referência para o piloto
A8: Revisões (DEC-012 — cada domínio é independente)
A9: Geometry REV | B9: G-REV-A
A10: Kinematics REV | B10: N/A (Fase 2)
A11: Tire REV | B11: N/A (Fase 2)
A12: Dynamics Script Version | B12: V2.0

Sheet 02_REQUIREMENTS
A1: 02_REQUIREMENTS
A3: Requisitos do Rulebook (FSAE Rules 2026 V1.0) pertinentes ao domínio já modelado
A4: ID | B4: Requirement | C4: Value | D4: Type | E4: Source | F4: Status | G4: Owner | H4: Revision
A5: REQ-001 | B5: Wheelbase mínimo (SUS-003) | C5: >= 1525 mm | D5: Geometry | E5: Rulebook V.1.2 | F5: ACTIVE | G5: N/A (externo) | H5: FSAE Rules 2026 V1.0
A6: REQ-002 | B6: Razão entre bitolas (SUS-004/SUS-005): a menor não pode ser < 75% da maior | C6: >= 0.75 (menor/maior) | D6: Geometry | E6: Rulebook V.1.3.2 | F6: ACTIVE | G6: N/A (externo) | H6: FSAE Rules 2026 V1.0
A7: REQ-003 | B7: Estabilidade ao capotamento: bitola + CG (SUS-002, SUS-004/005) devem combinar para o veículo não capotar no Tilt Test | C7: não capota a 60° de inclinação (~1.7g lateral equivalente) | D7: Safety | E7: Rulebook V.1.3.1 + IN.11.2.2 (Tilt Test) | F7: ACTIVE | G7: N/A (externo) | H7: FSAE Rules 2026 V1.0
A8: REQ-004 | B8: Curso útil mínimo de suspensão, dianteiro e traseiro, com piloto sentado | C8: >= 50 mm | D8: Competition | E8: Rulebook V.3.1.1 | F8: ACTIVE | G8: N/A (externo) | H8: FSAE Rules 2026 V1.0
A9: REQ-005 | B9: Diâmetro mínimo de roda (afeta estimativa de altura de CG não-suspenso, SUS-010/011) | C9: >= 203.2 mm (8.0 in) | D9: Components | E9: Rulebook V.4.1 | F9: ACTIVE | G9: N/A (externo) | H9: FSAE Rules 2026 V1.0
A10: REQ-006 | B10: Sistema de freio deve travar as 4 rodas com controle único e 2 circuitos hidráulicos independentes; para EV, ate 90% do curso do pedal pode ser regenerativo antes de acionar o hidraulico (contexto para SUS-013) | C10: 4 rodas / 2 circuitos / 90% pedal regen (EV) | D10: Safety | E10: Rulebook T.3.1.2, T.3.1.3, T.3.2.4 | F10: ACTIVE | G10: N/A (externo) | H10: FSAE Rules 2026 V1.0
A12: Requisitos acima vêm exclusivamente do Rulebook (FSAE Rules 2026 V1.0) - citação de regra exata em cada linha.
A13: Restrições próprias da equipe (Team/Packaging/Manufacturing) ainda NÃO foram definidas - serão adicionadas quando a equipe as fornecer, não antes.

Sheet 03_TARGETS
A1: 03_TARGETS
A3: Targets (aquilo que a equipe quer atingir) — ESTRUTURA, sem valores inventados
A4: ID | B4: Parameter | C4: Target | D4: Status | E4: Owner | F4: Decision | G4: Revision
A5: TARGET-001 | B5: Front Natural Frequency (SUS-205) | C5: TBD | D5: OPEN | E5: TBD | F5: - | G5: -
A6: TARGET-002 | B6: Rear Natural Frequency (SUS-205) | C6: TBD | D6: OPEN | E6: TBD | F6: - | G6: -
A7: TARGET-003 | B7: Roll Stiffness Distribution - lambda_f (SUS-208) | C7: TBD | D7: OPEN | E7: TBD | F7: - | G7: -
A8: TARGET-004 | B8: Anti-Dive % (SUS-301) | C8: TBD | D8: OPEN | E8: TBD | F8: - | G8: -
A9: TARGET-005 | B9: Anti-Squat % (SUS-302) | C9: TBD | D9: OPEN | E9: TBD | F9: - | G9: -
A11: 'Target' = TBD e Status = OPEN deliberadamente: nenhum valor-alvo real foi definido pela equipe ainda.
A12: Parametros como Motion Ratio, Spring Rate e Wheel Rate NAO viram Target aqui de proposito - sao consequencia de geometria/packaging/Design Mode, nao objetivos primarios.

Sheet 04_DECISION_REGISTER
A1: 04_DECISION_REGISTER
A3: Decisões já tomadas (arquitetura/física da V1) — registro consolidado (planilha + Guide, Apêndice E)
A4: ID | B4: Target/Escopo | C4: Decision | D4: Why | E4: Constraints | F4: Owner | G4: Status | H4: Origem
A5: DR-001 | B5: Convenções (todos os SUS-XXX) | C5: Sistema de coordenadas ISO 8855 (X-frente, Y-esquerda, Z-cima), destrogiro, sinais por regra da mao direita sem excecao intuitiva. | D5: Padrao internacional de dinamica veicular; evita ambiguidade entre pitch/roll/yaw ao importar dados de ferramentas externas. | E5: Compatibilidade com OptimumKinematics (configuravel) e Lotus (requer adapter de sinal). | F5: Mecanica (decisao de arquitetura) | G5: FROZEN | H5: Planilha + Guide
A6: DR-002 | B6: SUS-201/202 | C6: Motion Ratio definido como wheel travel / spring travel (nao a convencao inversa). | D6: Convencao unica evita erro de fator ao converter Ks<->Kw; nomenclatura explicita 'MR [wheel/spring]' obrigatoria. | E6: Nenhuma - decisao de nomenclatura interna. | F6: Mecanica (decisao de arquitetura) | G6: FROZEN | H6: Planilha + Guide
A7: DR-003 | B7: SUS-103 | C7: Modelo de duas molas de Milliken adotado como formulacao de referencia para transferencia lateral de carga. | D7: Formulacao padrao da literatura (Milliken, RCVD); verificada algebricamente (conservacao de momento), numericamente (Python+Excel) e cross-referenciada contra Chalmers/Sampo (transcricao identica termo a termo). | E7: Hipotese de superposicao linear; RC estatico (sem migracao dinamica). | F7: Mecanica (decisao de arquitetura) | G7: FROZEN | H7: Planilha + Guide
A8: DR-004 | B8: Todo o dominio de suspensao | C8: T09/E03 e a referencia historica de suspensao; TX/E05 nao contamina o baseline de dados de suspensao. | D8: Dados de suspensao do TX se mostraram parcialmente estimados/inconsistentes (ex.: ARB documentado mas nao efetivamente implementado); T09 tem planilha de calculo detalhada verificavel. | E8: Dados gerais de veiculo (massa, geometria) do TX permanecem utilizaveis quando o Design Case for aberto - a exclusao e so para comportamento/configuracao de suspensao. | F8: Mecanica (decisao de arquitetura) | G8: FROZEN | H8: Planilha + Guide
A9: DR-005 | B9: SUS-401 (Roll Center) | C9: V1 usa RC_static = RC(z_RH); sem migracao dinamica do roll center durante rolagem. | D9: Modelagem de RC(phi) exigiria acoplamento iterativo Vehicle State <-> KOP, fora do escopo da V1. | E9: Limitacao conhecida e documentada; OptimumKinematics assume essa responsabilidade na V2. | F9: Mecanica (decisao de arquitetura) | G9: FROZEN | H9: Planilha + Guide
A10: DR-006 | B10: SUS-301/SUS-302 | C10: Anti-dive e anti-squat nao alteram a magnitude da transferencia de carga longitudinal global - so descrevem a particao geometrica vs. elastica da reacao. | D10: Erro classico de interpretacao seria multiplicar o load transfer por (1-%AD); isso e fisicamente incorreto sob equilibrio de corpo rigido. | E10: Nenhuma equacao de load transfer deve referenciar %AD/%AS como fator multiplicativo. | F10: Mecanica (decisao de arquitetura) | G10: FROZEN | H10: Planilha + Guide
A11: DR-007 | B11: SUS-701/SUS-702 | C11: Aero da V1 limitado a downforce total + aero balance dianteiro, ambos constantes por Setup (sem F_aero(v), sem CFD). | D11: Evita 'fisica implicita' no Excel sem Engineering Standard formal para aero dependente de velocidade. | E11: Se aero dependente de velocidade for necessario no futuro, exige nova ficha SUS-7XX formal antes de implementar. | F11: Mecanica (decisao de arquitetura) | G11: FROZEN | H11: Planilha + Guide
A12: DR-008 | B12: Arquitetura Excel/Python | C12: Nenhuma bridge automatica Python<->Excel na V1; Excel possui implementacao propria das formulas, Python e motor independente, ambos comparados manualmente. | D12: Bridge JSON/CSV e um projeto proprio; construir isso antes de validar o modelo fisico inverteria a prioridade. | E12: Quando a bridge existir, as formulas do Excel permanecem como cross-check independente, nao sao descartadas. | F12: Mecanica (decisao de arquitetura) | G12: n/d | H12: Planilha
A13: DR-009 | B13: SUS-402 e SUS-406 (início da V2) | C13: SUS-402 (Roll Center via IC em vista frontal) e SUS-406 (Instant Center em vista lateral, para Anti-Dive/Anti-Squat) formalizados e implementados apenas em Python (kinematics_model_V2_0.py), nao em formula nativa do Excel. | D13: A dupla interseccao de retas 2D produziria uma formula de planilha longa e ilegivel; verificado com casos de teste sinteticos (11/11 PASS no total, incluindo simetria de espelhamento e casos degenerados de retas paralelas) antes de qualquer hardpoint real existir. SUS-406 usa ponto medio das buchas como proxy do eixo de pivo em vista lateral (diferente do SUS-402, que usa o mesmo ponto para vista frontal) - aproximacao de primeira ordem documentada na ficha. Guide (DR-009): solver cinematico interno fora da V1, motivo "evitar duplicacao". | E13: Nunca autoritativo (Data Type MODEL, proposito cross-check) - OptimumKinematics continua sendo REFERENCE oficial (SUS-401/SUS-406) quando integrado. Ainda nao conectado ao Excel - aguarda o hardpoint schema (proximo passo da V2). | F13: Mecanica (decisao de arquitetura) | G13: FROZEN | H13: Planilha + Guide (Guide: DR-009)
A14: DR-010 | B14: SUS-202 / SUS-205 (Design Mode) | C14: Design Mode explicito: o calculo reverso deve indicar qual variavel e o alvo e qual e resolvida; sem goal seek opaco. | D14: Evitar goal seek opaco e o uso da mesma equacao no sentido errado (Guide, Apendice B.3). | E14: Design Mode nao cria fichas proprias: e a equacao reversa dentro de SUS-202/205 (Engineering Standard, Bloco J). Equacao reversa de roll stiffness (SUS-206/207) ainda nao escrita no Standard. Valores de 2,5/2,7 Hz e lambda_f 0,55 em 11_DESIGN sao demonstrativos, nao TARGET (Guide, cap. 4.11 e Apendice F.2). | F14: Mecanica (decisao de arquitetura) | G14: FROZEN | H14: Guide
A15: DR-011 | B15: SUS-501 / SUS-502 / SUS-503 (Tire) | C15: Pneu consumido como REFERENCE (OptimumTire/TTC), sem ajuste (fit) proprio na V1. | D15: Sem fit proprio na V1 (Guide, Apendice E). Numeracao: no Guide esta decisao aparece como DR-008. | E15: Nivel 1 (lookup) ou nivel 2 (parametrico) conforme DEC-007 (Engineering Standard). Verificar a convencao de sinal de alpha e de slip ratio exportada contra ISO 8855 antes de consumir. 10_TIRE aguarda a Fase 2. | F15: Mecanica (decisao de arquitetura) | G15: FROZEN | H15: Guide
A16: DR-012 | B16: SUS-407..413 (Kinematics Model); SUS-406/301/302 (propostas); schema de hardpoints | C16: Solver cinematico 3D de double wishbone implementado em Python (kinematics_model_V2_0.py) como MODEL/cross-check, a partir de hardpoints.csv (schema V2.0). Nunca substitui o OptimumKinematics (REFERENCE). | D16: Pedido do usuario: Kinematics o mais completa possivel na V2; DR-009 ja previa o solver interno para a V2. Formulacao verificada por solver independente, casos analiticos e teste de mutacao (47 testes de kinematics, 21 de hardpoints). | E16: PROPOSTAS aguardando aprovacao, NAO aplicadas ao 06_SUSPENSION: (1) IC lateral cinematico no lugar do metodo outer->ponto medio (SUS-406 V1); (2) %AD/%AS com sinal fisico no lugar de |d|; (3) IDs SUS-407..413 e schema de hardpoints. Sem hardpoints reais, TC-011 segue NOT_VALIDATED. Limite de aviso de MR (0,2) e vocabulario de Status/Component sao hipoteses. | F16: Mecanica (decisao de arquitetura) | G16: DRAFT | H16: V2.0 (proposta)
A17: Status = Estado do Guide (Apendice E.1). DR-008 nao tem estado registrado em nenhum documento (n/d). Origem "Guide" = decisao que so existia no Guide.
A18: Fonte oficial consolidada de decisões: Engineering_Decision_Register.md (EDR-xxx). Esta aba é espelho resumido (DR-xxx); em caso de divergência, vale o EDR.

Sheet 05_VEHICLE
A1: 05_VEHICLE
A3: Massa e Geometria
A4: Massa total (com piloto) | B4: 316.5 | C4: kg | D4: SUS-001
A5: Altura do CG (total) | B5: 0.315 | C5: m | D5: SUS-002
A6: Wheelbase (L) | B6: 1.594 | C6: m | D6: SUS-003
A7: Front Track (t_F) | B7: 1.277 | C7: m | D7: SUS-004
A8: Rear Track (t_R) | B8: 1.271 | C8: m | D8: SUS-005
A9: CG -> eixo dianteiro (a) | B9: 0.82203 | C9: m | D9: SUS-006
A10: CG -> eixo traseiro (b) | B10: 0.77197 | C10: m | D10: SUS-006
A11: Checagem: a + b = L (deve ser 0) | B11: ='05_VEHICLE'!$B$9+'05_VEHICLE'!$B$10-'05_VEHICLE'!$B$6
A13: Massas não-suspensas
A14: Massa não-suspensa dianteira | B14: 15 | C14: kg | D14: SUS-007
A15: Massa não-suspensa traseira | B15: 18 | C15: kg | D15: SUS-008
A16: Altura CG não-suspenso dianteiro | B16: 0.254 | C16: m | D16: SUS-010
A17: Altura CG não-suspenso traseiro | B17: 0.254 | C17: m | D17: SUS-011
A19: Referência de solo
A20: Ground Plane Z (offset origem CAD -> solo) | B20: -0.05 | C20: m | D20: SUS-000
A22: Calculado (SUS-009 / SUS-012)
A23: Massa suspensa total | B23: ='05_VEHICLE'!$B$4-'05_VEHICLE'!$B$14-'05_VEHICLE'!$B$15 | C23: kg | D23: SUS-009
A24: Altura do CG suspenso (h_s) | B24: =('05_VEHICLE'!$B$4*'05_VEHICLE'!$B$5-'05_VEHICLE'!$B$14*'05_VEHICLE'!$B$16-'05_VEHICLE'!$B$15*'05_VEHICLE'!$B$17)/'05_VEHICLE'!$B$23 | C24: m | D24: SUS-012

Sheet 06_SUSPENSION
A1: 06_SUSPENSION
A3: Mola / Motion Ratio
A4: Spring Rate dianteiro | B4: 49909.24 | C4: N/m | D4: SUS-203
A5: Spring Rate traseiro | B5: 57052.22 | C5: N/m | D5: SUS-203
A6: Motion Ratio dianteiro [wheel/spring] | B6: 1.76 | C6: - | D6: SUS-201
A7: Motion Ratio traseiro [wheel/spring] | B7: 1.76 | C7: - | D7: SUS-201
A9: Anti-Roll Bar (simplificação V1 — sem cinemática interna)
A10: K_ARB dianteiro | B10: 5012.32 | C10: N*m/rad | D10: SUS-206
A11: K_ARB traseiro | B11: 10.78 | C11: N*m/rad | D11: SUS-207
A13: Roll Center — PROVISÓRIO (Fase 2 substitui por REFERENCE do OptimumKinematics)
A14: Roll Center dianteiro (RH estático) | B14: 0.0675 | C14: m | D14: SUS-401-F
A15: Roll Center traseiro (RH estático) | B15: 0.11 | C15: m | D15: SUS-401-R
A17: Calculado — Wheel Rate / Roll Stiffness (SUS-202/206/207/208)
A18: Wheel Rate dianteiro | B18: ='06_SUSPENSION'!$B$4/'06_SUSPENSION'!$B$6^2 | C18: N/m | D18: SUS-202
A19: Wheel Rate traseiro | B19: ='06_SUSPENSION'!$B$5/'06_SUSPENSION'!$B$7^2 | C19: N/m | D19: SUS-202
A20: Roll Stiffness sem ARB - dianteira | B20: ='06_SUSPENSION'!$B$18*'05_VEHICLE'!$B$7^2/2 | C20: N*m/rad | D20: SUS-206
A21: Roll Stiffness sem ARB - traseira | B21: ='06_SUSPENSION'!$B$19*'05_VEHICLE'!$B$8^2/2 | C21: N*m/rad | D21: SUS-207
A22: Roll Stiffness dianteira (K_phiF) | B22: ='06_SUSPENSION'!$B$20+'06_SUSPENSION'!$B$10 | C22: N*m/rad | D22: SUS-206
A23: Roll Stiffness traseira (K_phiR) | B23: ='06_SUSPENSION'!$B$21+'06_SUSPENSION'!$B$11 | C23: N*m/rad | D23: SUS-207
A24: Distribuição de rigidez - dianteira (lambda_f) | B24: ='06_SUSPENSION'!$B$22/('06_SUSPENSION'!$B$22+'06_SUSPENSION'!$B$23) | C24: - | D24: SUS-208
A25: Distribuição de rigidez - traseira (lambda_r) | B25: ='06_SUSPENSION'!$B$23/('06_SUSPENSION'!$B$22+'06_SUSPENSION'!$B$23) | C25: - | D25: SUS-208
A27: Massa suspensa por canto (SUS-009, distribuição)
A28: Massa suspensa por canto - dianteira | B28: ='05_VEHICLE'!$B$23*('05_VEHICLE'!$B$10/'05_VEHICLE'!$B$6)/2 | C28: kg | D28: SUS-009
A29: Massa suspensa por canto - traseira | B29: ='05_VEHICLE'!$B$23*('05_VEHICLE'!$B$9/'05_VEHICLE'!$B$6)/2 | C29: kg | D29: SUS-009
A31: Frequência Natural (SUS-205)
A32: Frequência Natural dianteira | B32: =(1/(2*PI()))*SQRT('06_SUSPENSION'!$B$18/'06_SUSPENSION'!$B$28) | C32: Hz | D32: SUS-205
A33: Frequência Natural traseira | B33: =(1/(2*PI()))*SQRT('06_SUSPENSION'!$B$19/'06_SUSPENSION'!$B$29) | C33: Hz | D33: SUS-205
A34: Anti-Dive / Anti-Squat (SUS-301/302) — Lifecycle: DRAFT->CHECKED
A35: Metodologia FROZEN (Milliken); linha geométrica (contact patch vs. wheel center) pendente de confirmação com a config. real de freio/trem de força.
A36: Front Brake Force Fraction (FB_f) | B36: 0.6 | C36: - | D36: SUS-013
A37: Rear Traction Force Fraction (TF_r) | B37: 1 | C37: - | D37: SUS-014
A38: tan(phi_f) — dianteiro (a partir do IC lateral) | B38: ='07_KINEMATICS'!$B$10/'07_KINEMATICS'!$B$11 | C38: - | D38: SUS-406-F
A39: tan(phi_r) — traseiro (a partir do IC lateral) | B39: ='07_KINEMATICS'!$B$12/'07_KINEMATICS'!$B$13 | C39: - | D39: SUS-406-R
A40: Anti-Dive (%) | B40: ='06_SUSPENSION'!$B$36*'06_SUSPENSION'!$B$38*('05_VEHICLE'!$B$6/'05_VEHICLE'!$B$5)*100 | C40: % | D40: SUS-301
A41: Anti-Squat (%) | B41: ='06_SUSPENSION'!$B$37*'06_SUSPENSION'!$B$39*('05_VEHICLE'!$B$6/'05_VEHICLE'!$B$5)*100 | C41: % | D41: SUS-302
A43: Steering (SUS-601) — escopo reduzido, sem Ackermann/bump steer
A44: Steering Ratio (SR) | B44: 4.5 | C44: - | D44: SUS-601

Sheet 07_KINEMATICS
A1: 07_KINEMATICS
A3: Status: PROVISÓRIO (estrutura pronta; valores abaixo NÃO vêm do OptimumKinematics ainda)
A4: Todos os campos desta aba são PLACEHOLDER até a Fase 2 (integração real com OptimumKinematics). Servem para a fórmula de Anti-Dive/Anti-Squat funcionar de ponta a ponta antes de existir dado real.
A6: Kinematic Operating Point (KOP) ativo
A7: KOP | B7: Ride Height Estático (RH) | C7: - | D7: -
A9: Instant Center — Vista Lateral (SUS-406) — usado por Anti-Dive/Anti-Squat
A10: Altura do IC lateral dianteiro (z_ICF) | B10: 0.2 | C10: m | D10: SUS-406-F
A11: Distância contact patch->IC, dianteiro (vista lateral) | B11: 2.5 | C11: m | D11: SUS-406-F
A12: Altura do IC lateral traseiro (z_ICR) | B12: 0.25 | C12: m | D12: SUS-406-R
A13: Distância contact patch->IC, traseiro (vista lateral) | B13: 2 | C13: m | D13: SUS-406-R
A15: Instant Center — Vista Frontal (SUS-403) — cross-check de RC (SUS-402) via Python
A16: SUS-402 (RC via interseção geométrica do IC frontal) foi formalizado e implementado em kinematics_model_V2_0.py (V2) - testado 11/11 (SUS-402 e SUS-406) com geometria sintética (DR-009). NÃO implementado em fórmula do Excel (complexidade de dupla interseção 2D não compensa em planilha). Os campos abaixo alimentariam esse script quando hardpoints reais existirem; hoje são só posição de referência.
A17: Y do IC frontal dianteiro | B17: 1.5 | C17: m | D17: SUS-403-F
A18: Z do IC frontal dianteiro | B18: 0.15 | C18: m | D18: SUS-403-F
A19: Y do IC frontal traseiro | B19: 1.8 | C19: m | D19: SUS-403-R
A20: Z do IC frontal traseiro | B20: 0.2 | C20: m | D20: SUS-403-R
A22: Camber Gain (SUS-404) — não alimenta nenhum cálculo de carga da V1, só REFERENCE
A23: Camber Gain dianteiro (dCamber/dz) | B23: -0.6 | C23: deg/mm | D23: SUS-404-F
A24: Camber Gain traseiro (dCamber/dz) | B24: -0.5 | C24: deg/mm | D24: SUS-404-R
A26: Toe Curve (SUS-405) — não alimenta nenhum cálculo de carga da V1, só REFERENCE
A27: Toe Gain dianteiro (dToe/dz) | B27: 0.05 | C27: deg/mm | D27: SUS-405-F
A28: Toe Gain traseiro (dToe/dz) | B28: 0.05 | C28: deg/mm | D28: SUS-405-R
A30: Curso de Suspensão Disponível — para checagem contra REQ-004 (>=50mm)
A31: Curso útil disponível - dianteiro (bump+rebound) | B31: 60 | C31: mm | D31: -
A32: Curso útil disponível - traseiro (bump+rebound) | B32: 65 | C32: mm | D32: -
A34: V2.0 — Resultados do solver cinemático (Python; cross-check, nunca REFERENCE)
A35: Origem: kinematics_model_V2_0.py -> kinematics_sweep_<canto>.csv (Data Contract V2.0, seção 6). Atualização manual até existir bridge (DR-008). Preencher SOMENTE com hardpoints reais (Status diferente de SYNTHETIC). Enquanto não houver, os campos ficam N/A. O Excel não recalcula cinemática (DR-009).
A36: Camber estático - dianteiro | B36: N/A | C36: deg | D36: SUS-407 | E36: sem hardpoints reais
A37: Camber estático - traseiro | B37: N/A | C37: deg | D37: SUS-407 | E37: sem hardpoints reais
A38: Camber gain (dγ/dz) - dianteiro | B38: N/A | C38: deg/mm | D38: SUS-407 | E38: sem hardpoints reais
A39: Camber gain (dγ/dz) - traseiro | B39: N/A | C39: deg/mm | D39: SUS-407 | E39: sem hardpoints reais
A40: Toe estático - dianteiro | B40: N/A | C40: deg | D40: SUS-408 | E40: sem hardpoints reais
A41: Toe estático - traseiro | B41: N/A | C41: deg | D41: SUS-408 | E41: sem hardpoints reais
A42: Bump steer (dδ/dz) - dianteiro | B42: N/A | C42: deg/mm | D42: SUS-408 | E42: sem hardpoints reais
A43: Bump steer (dδ/dz) - traseiro | B43: N/A | C43: deg/mm | D43: SUS-408 | E43: sem hardpoints reais
A44: Caster - dianteiro | B44: N/A | C44: deg | D44: SUS-410 | E44: sem hardpoints reais
A45: Caster - traseiro | B45: N/A | C45: deg | D45: SUS-410 | E45: sem hardpoints reais
A46: KPI - dianteiro | B46: N/A | C46: deg | D46: SUS-410 | E46: sem hardpoints reais
A47: KPI - traseiro | B47: N/A | C47: deg | D47: SUS-410 | E47: sem hardpoints reais
... A61: Inclinação da linha de força lateral (dz/dx) - traseiro | B61: N/A | C61: - | D61: SUS-412 | E61: sem hardpoints reais
...

Sheet 08_VEHICLE_STATE
A1: 08_VEHICLE_STATE
A3: Estado do veículo (manobra)
A4: Aceleração longitudinal (a_x) | B4: -5 | C4: m/s^2 | D4: -
A5: Aceleração lateral (a_y) | B5: 11.772 | C5: m/s^2 | D5: -
A7: Aero (constante por Setup — SUS-701/702, sem F_aero(v) na V1)
A8: Downforce total | B8: 400 | C8: N | D8: SUS-701
A9: Aero Balance (fração dianteira) | B9: 0.45 | C9: - | D9: SUS-702

Sheet 09_LOADS
A1: 09_LOADS
A3: Carga Estática (SUS-101)
A4: Carga estática eixo dianteiro (W_f) | B4: ='05_VEHICLE'!$B$4*9.81*('05_VEHICLE'!$B$10/'05_VEHICLE'!$B$6) | C4: N | D4: SUS-101
A5: Carga estática eixo traseiro (W_r) | B5: ='05_VEHICLE'!$B$4*9.81*('05_VEHICLE'!$B$9/'05_VEHICLE'!$B$6) | C5: N | D5: SUS-101
A6: Fz estático FL | B6: ='09_LOADS'!$B$4/2 | C6: N | D6: SUS-101
A7: Fz estático FR | B7: ='09_LOADS'!$B$4/2 | C7: N | D7: SUS-101
A8: Fz estático RL | B8: ='09_LOADS'!$B$5/2 | C8: N | D8: SUS-101
A9: Fz estático RR | B9: ='09_LOADS'!$B$5/2 | C9: N | D9: SUS-101
A11: Transferência Longitudinal (SUS-102)
A12: dFz longitudinal - eixo dianteiro | B12: =-'05_VEHICLE'!$B$4*'08_VEHICLE_STATE'!$B$4*'05_VEHICLE'!$B$5/'05_VEHICLE'!$B$6 | C12: N | D12: SUS-102
A13: dFz longitudinal - eixo traseiro | B13: =+'05_VEHICLE'!$B$4*'08_VEHICLE_STATE'!$B$4*'05_VEHICLE'!$B$5/'05_VEHICLE'!$B$6 | C13: N | D13: SUS-102
A14: dFz longitudinal por canto - dianteira | B14: ='09_LOADS'!$B$12/2 | C14: N | D14: SUS-102
A15: dFz longitudinal por canto - traseira | B15: ='09_LOADS'!$B$13/2 | C15: N | D15: SUS-102
A17: Transferência Lateral — Milliken two-spring (SUS-103)
A18: Altura do roll axis no CG (z_s) | B18: =('05_VEHICLE'!$B$10/'05_VEHICLE'!$B$6)*'06_SUSPENSION'!$B$14+('05_VEHICLE'!$B$9/'05_VEHICLE'!$B$6)*'06_SUSPENSION'!$B$15 | C18: m | D18: -
A19: dFz lateral - eixo dianteiro | B19: =('08_VEHICLE_STATE'!$B$5/'05_VEHICLE'!$B$7)*('06_SUSPENSION'!$B$24*'05_VEHICLE'!$B$23*('05_VEHICLE'!$B$24-'09_LOADS'!$B$18)+('05_VEHICLE'!$B$10/'05_VEHICLE'!$B$6)*'05_VEHICLE'!$B$23*'06_SUSPENSION'!$B$14+'05_VEHICLE'!$B$14*'05_VEHICLE'!$B$16) | C19: N | D19: SUS-103
A20: dFz lateral - eixo traseiro | B20: =('08_VEHICLE_STATE'!$B$5/'05_VEHICLE'!$B$8)*('06_SUSPENSION'!$B$25*'05_VEHICLE'!$B$23*('05_VEHICLE'!$B$24-'09_LOADS'!$B$18)+('05_VEHICLE'!$B$9/'05_VEHICLE'!$B$6)*'05_VEHICLE'!$B$23*'06_SUSPENSION'!$B$15+'05_VEHICLE'!$B$15*'05_VEHICLE'!$B$17) | C20: N | D20: SUS-103
A22: Aero por canto (SUS-701/702)
A23: Fz aero - eixo dianteiro | B23: ='08_VEHICLE_STATE'!$B$8*'08_VEHICLE_STATE'!$B$9 | C23: N | D23: -
A24: Fz aero - eixo traseiro | B24: ='08_VEHICLE_STATE'!$B$8*(1-'08_VEHICLE_STATE'!$B$9) | C24: N | D24: -
A25: Fz aero FL | B25: ='09_LOADS'!$B$23/2 | C25: N | D25: -
A26: Fz aero FR | B26: ='09_LOADS'!$B$23/2 | C26: N | D26: -
A27: Fz aero RL | B27: ='09_LOADS'!$B$24/2 | C27: N | D27: -
A28: Fz aero RR | B28: ='09_LOADS'!$B$24/2 | C28: N | D28: -
A30: Fz Combinado por Canto (SUS-104)
A31: Fz FL | B31: ='09_LOADS'!$B$6+'09_LOADS'!$B$14-'09_LOADS'!$B$19+'09_LOADS'!$B$25 | C31: N | D31: SUS-104
A32: Fz FR | B32: ='09_LOADS'!$B$7+'09_LOADS'!$B$14+'09_LOADS'!$B$19+'09_LOADS'!$B$26 | C32: N | D32: SUS-104
A33: Fz RL | B33: ='09_LOADS'!$B$8+'09_LOADS'!$B$15-'09_LOADS'!$B$20+'09_LOADS'!$B$27 | C33: N | D33: SUS-104
A34: Fz RR | B34: ='09_LOADS'!$B$9+'09_LOADS'!$B$15+'09_LOADS'!$B$20+'09_LOADS'!$B$28 | C34: N | D34: SUS-104

Sheet 10_TIRE
A1: 10_TIRE
A3: Status: WAITING INPUT (Fase 2 - integração com OptimumTire)
A4: Esta aba existe estruturalmente desde a V1, mas depende do OptimumTire (ainda nao integrado).
A6: Campos previstos (fichas SUS-501/502/503 do Engineering Standard):
A7: - Fy(Fz, alpha, gamma) - REFERENCE do dataset OptimumTire
A8: - Fx(Fz, slip) - REFERENCE
A9: - mu efetivo - CALCULATED a partir de Fx/Fy/Fz
A11: Load Transfer (09_LOADS) NAO depende desta aba - a causalidade e Vehicle State -> Load Transfer -> Fz by
A12: corner -> Tire Model, nunca o inverso.

Sheet 11_DESIGN
A1: 11_DESIGN — Design Mode
A3: Target de frequência (TARGET-XXX)
A4: Frequência-alvo dianteira | B4: 2.5 | C4: Hz | D4: TARGET-001
A5: Frequência-alvo traseira | B5: 2.7 | C5: Hz | D5: TARGET-002
A7: Rigidez necessária (equação reversa, SUS-202/205)
A8: Wheel Rate necessário - dianteira | B8: =(2*PI()*'11_DESIGN'!$B$4)^2*'06_SUSPENSION'!$B$28 | C8: N/m | D8: SUS-205
A9: Wheel Rate necessário - traseira | B9: =(2*PI()*'11_DESIGN'!$B$5)^2*'06_SUSPENSION'!$B$29 | C9: N/m | D9: SUS-205
A10: Spring Rate necessário - dianteira | B10: ='11_DESIGN'!$B$8*'06_SUSPENSION'!$B$6^2 | C10: N/m | D10: SUS-202
A11: Spring Rate necessário - traseira | B11: ='11_DESIGN'!$B$9*'06_SUSPENSION'!$B$7^2 | C11: N/m | D11: SUS-202
A13: Comparação com o Spring Rate atual (06_SUSPENSION)
A14: Diferença dianteira (necessário - atual) | B14: ='11_DESIGN'!$B$10-'06_SUSPENSION'!$B$4 | C14: N/m | D14: -
A15: Diferença traseira (necessário - atual) | B15: ='11_DESIGN'!$B$11-'06_SUSPENSION'!$B$5 | C15: N/m | D15: -
A17: Target de Roll Stiffness Distribution (equação reversa, SUS-208 — DRAFT, ver Engineering Standard)
A18: lambda_f alvo | B18: 0.55 | C18: - | D18: TARGET-003
A19: Roll Stiffness dianteira necessária (K_phiF total) | B19: =('11_DESIGN'!$B$18/(1-'11_DESIGN'!$B$18))*'06_SUSPENSION'!$B$23 | C19: N*m/rad | D19: SUS-208
A20: K_ARB dianteiro necessário | B20: ='11_DESIGN'!$B$19-'06_SUSPENSION'!$B$20 | C20: N*m/rad | D20: SUS-206
A21: Diferença K_ARB dianteiro (necessário - atual) | B21: ='11_DESIGN'!$B$20-'06_SUSPENSION'!$B$10 | C21: N*m/rad | D21: -

Sheet 12_COMPARISON
A1: 12_COMPARISON
A3: Comparação entre Setups/alternativas — vazio até existir mais de um Setup real
A4: Estrutura reservada. Nao ha ainda um segundo Setup real do Design Case para comparar contra o Baseline.
A5: Preencher quando houver pelo menos duas configuracoes concretas a comparar (evita aba decorativa vazia).

Sheet 13_VALIDATION
A1: 13_VALIDATION
A3: Self-checks de conservação (equivalentes a TC-004 / TC-005 / lambda)
A4: TC-004: Sum(Fz) - (W+Faero) [deve ser ~0] | B4: ='09_LOADS'!$B$31+'09_LOADS'!$B$32+'09_LOADS'!$B$33+'09_LOADS'!$B$34-('05_VEHICLE'!$B$4*9.81+'08_VEHICLE_STATE'!$B$8) | C4: N | D4: TC-004
A5: Status TC-004 | B5: =IF(ABS('13_VALIDATION'!$B$4)<0.01,"PASS","FAIL") | C5: - | D5: -
A6: TC-005: t_F*dFzF + t_R*dFzR - m*ay*h_CG [deve ser ~0] | B6: ='05_VEHICLE'!$B$7*'09_LOADS'!$B$19+'05_VEHICLE'!$B$8*'09_LOADS'!$B$20-'05_VEHICLE'!$B$4*'08_VEHICLE_STATE'!$B$5*'05_VEHICLE'!$B$5 | C6: N*m | D6: TC-005
A7: Status TC-005 | B7: =IF(ABS('13_VALIDATION'!$B$6)<0.01,"PASS","FAIL") | C7: - | D7: -
A8: Checagem: lambda_f + lambda_r = 1 | B8: ='06_SUSPENSION'!$B$24+'06_SUSPENSION'!$B$25 | C8: - | D8: SUS-208
A10: Plausibilidade — perda de contato (Fz < 0 invalida o modelo linear, ver SUS-104)
A11: Fz FL >= 0 ? | B11: =IF('09_LOADS'!$B$31>=0,"OK","WARNING: perda de contato") | C11: - | D11: -
A12: Fz FR >= 0 ? | B12: =IF('09_LOADS'!$B$32>=0,"OK","WARNING: perda de contato") | C12: - | D12: -
A13: Fz RL >= 0 ? | B13: =IF('09_LOADS'!$B$33>=0,"OK","WARNING: perda de contato") | C13: - | D13: -
A14: Fz RR >= 0 ? | B14: =IF('09_LOADS'!$B$34>=0,"OK","WARNING: perda de contato") | C14: - | D14: -
A16: Checagem contra Requirements (02_REQUIREMENTS)
A17: tan(ângulo de tombamento) — usa a MENOR bitola (pior caso) | B17: =(MIN('05_VEHICLE'!$B$7,'05_VEHICLE'!$B$8)/2)/'05_VEHICLE'!$B$5 | C17: - | D17: REQ-003
A18: Ângulo de tombamento (graus) | B18: =DEGREES(ATAN('13_VALIDATION'!$B$17)) | C18: deg | D18: REQ-003
A19: Status REQ-003 (Tilt Test, mínimo 60°) | B19: =IF('13_VALIDATION'!$B$18>=60,"PASS","FAIL - risco de reprovacao no Tilt Test") | C19: - | D19: REQ-003
A21: Status REQ-004 (curso dianteiro, mínimo 50mm) | B21: =IF('07_KINEMATICS'!$B$31>=50,"PASS","FAIL") | C21: - | D21: REQ-004
A22: Status REQ-004 (curso traseiro, mínimo 50mm) | B22: =IF('07_KINEMATICS'!$B$32>=50,"PASS","FAIL") | C22: - | D22: REQ-004
A24: Referência — resultado do piloto Python (atualizar manualmente até o bridge existir)
A25: 16/16 Test Cases PASS em suspension_model_V2_0.py / test_suspension_model_V2_0.py (ver Engineering Standard V2.0, Log de Validação)
A26: Piloto de referência: MR=0.8, Ks=100 N/mm, ms=50 kg -> fn=8.897 Hz (verificado)
A28: Checagem adicional de requisitos (V2.1) — REQ-001 e REQ-002 (02_REQUIREMENTS; Rulebook V.1.2 e V.1.3.2)
A29: Wheelbase (mm) — a partir de 05_VEHICLE!B6 | B29: =IF(ISNUMBER('05_VEHICLE'!$B$6),'05_VEHICLE'!$B$6*1000,"N/A") | C29: mm | D29: REQ-001
A30: Status REQ-001 (wheelbase mínimo 1525 mm) | B30: =IF(ISNUMBER($B$29),IF($B$29>=1525,"PASS","FAIL - wheelbase abaixo do mínimo (V.1.2)"),"N/A - dado ausente") | C30: - | D30: REQ-001
A31: Razão entre bitolas (menor/maior) — 05_VEHICLE!B7 e B8 | B31: =IF(AND(ISNUMBER('05_VEHICLE'!$B$7),ISNUMBER('05_VEHICLE'!$B$8)),MIN('05_VEHICLE'!$B$7,'05_VEHICLE'!$B$8)/MAX('05_VEHICLE'!$B$7,'05_VEHICLE'!$B$8),"N/A") | C31: - | D31: REQ-002
A32: Status REQ-002 (razão de bitolas mínima 0,75) | B32: =IF(ISNUMBER($B$31),IF($B$31>=0.75,"PASS","FAIL - razão de bitolas abaixo de 0,75 (V.1.3.2)"),"N/A - dado ausente") | C32: - | D32: REQ-002
A33: Dados de entrada: E05 Key Parameters (comentários de 05_VEHICLE B6/B7/B8) — especificação, não medição independente. Estado de validação: NOT_VALIDATED (sem medição física).

Sheet 14_DASHBOARD
A1: 14_DASHBOARD
A3: Setup ativo
A4: Setup | B4: ='01_SETUP'!$B$4&" - "&'01_SETUP'!$B$5 | C4: - | D4: -
A6: Fz por canto (N)
A7: Fz FL | B7: ='09_LOADS'!$B$31 | C7: N | D7: SUS-104
A8: Fz FR | B8: ='09_LOADS'!$B$32 | C8: N | D8: SUS-104
A9: Fz RL | B9: ='09_LOADS'!$B$33 | C9: N | D9: SUS-104
A10: Fz RR | B10: ='09_LOADS'!$B$34 | C10: N | D10: SUS-104
A12: Rigidez e Frequência
A13: Wheel Rate dianteiro | B13: ='06_SUSPENSION'!$B$18 | C13: N/m | D13: SUS-202
A14: Wheel Rate traseiro | B14: ='06_SUSPENSION'!$B$19 | C14: N/m | D14: SUS-202
A15: Frequência Natural dianteira | B15: ='06_SUSPENSION'!$B$32 | C15: Hz | D15: SUS-205
A16: Frequência Natural traseira | B16: ='06_SUSPENSION'!$B$33 | C16: Hz | D16: SUS-205
A17: Distribuição de rigidez dianteira | B17: ='06_SUSPENSION'!$B$24 | C17: - | D17: SUS-208
A19: Status de Validação
A20: TC-004 (conservação de carga) | B20: ='13_VALIDATION'!$B$5 | C20: - | D20: -
A21: TC-005 (conservação de momento lateral) | B21: ='13_VALIDATION'!$B$7 | C21: - | D21: -
A22: REQ-003 (Tilt Test) | B22: ='13_VALIDATION'!$B$19 | C22: - | D22: -
A23: REQ-004 (curso dianteiro) | B23: ='13_VALIDATION'!$B$21 | C23: - | D23: -
A24: REQ-004 (curso traseiro) | B24: ='13_VALIDATION'!$B$22 | C24: - | D24: -
A26: Governança — Requirements / Targets / Decisions
A27: Requirements registrados | B27: =COUNTIF('02_REQUIREMENTS'!A:A,"REQ-*") | C27: - | D27: -
A28: Targets registrados | B28: =COUNTIF('03_TARGETS'!A:A,"TARGET-*") | C28: - | D28: -
A29: Targets em OPEN (sem valor real definido) | B29: =COUNTIF('03_TARGETS'!D:D,"OPEN") | C29: - | D29: -
A30: Decision Records registrados | B30: =COUNTIF('04_DECISION_REGISTER'!A:A,"DR-*") | C30: - | D30: -

Sheet 15_CHANGELOG
A1: 15_CHANGELOG
A3: Data | B3: Mudança | C3: Motivo
A4: 2026-09 | B4: Migracao da arquitetura de 9 para 16 abas (00_README...15_CHANGELOG) | C4: Sistema evoluiu de 'planilha de suspensao' para sistema de engenharia/memoria institucional da Mecanica
A5: 2026-09 | B5: Abas renomeadas (02_VEHICLE->05_VEHICLE, 03_SUSPENSION->06_SUSPENSION, etc.) via rename nativo do Excel | C5: Evitar reescrita manual de formulas - Excel atualiza referencias automaticamente ao renomear aba
A6: 2026-09 | B6: SUS-103 (Milliken two-spring) cross-referenciado contra Chalmers/Sampo | C6: Transcricao conferida termo a termo contra fonte externa publicada - identica, sem divergencia
A7: 2026-09 | B7: Wheel Rate do T09 corrigido de 21950 N/m (ambos os eixos) para 16112.23 F / 18418.2 R N/m | C7: Valor antigo vinha do spec sheet resumido (impreciso); planilha de calculo detalhada do T09 e mais confiavel
A8: 2026-09 | B8: Natural Frequency reclassificada de NOT_VALIDATED para PASS no T09 Reference Case | C8: Massa suspensa real do T09 (nao a nao-suspensa) e suficiente para a formula SUS-205; erro de entendimento anterior corrigido
A9: 2026-10 | B9: Decision Register consolidado: mantidas DR-001 a DR-009 da planilha (mais completas: Why/Constraints/Owner); adicionadas colunas Status e Origem; incluidas DR-010 (Design Mode explicito) e DR-011 (Tire como REFERENCE), vindas so do Guide. | C9: Planilha e Guide tinham versoes diferentes. Guide DR-008 (Tire) renumerado para DR-011 porque DR-008 da planilha (sem bridge Python-Excel) e outra decisao; Guide DR-009 ("solver interno nao e V1") tratado como a mesma decisao da DR-009 da planilha (Python-only, inicio da V2). Guide a alinhar depois.
A10: 2026-10 | B10: V1.0: versionamento dos artefatos (Standard, Arquitetura, Data Contract, suspension_model, kinematics_model e testes, planilha). README: versao V1.0 e correcao do aviso de Anti-dive/squat (ja implementados com placeholders); 07_KINEMATICS: 11/11; referencias de arquivo atualizadas para *_V1_0. | C10: Regra de versao: V1.0 -> V1.1 a cada pequena implementacao. Detalhes e divergencias abertas em registro-de-versoes-V1.0.md. Nenhuma formula foi alterada.
A11: 2026-10 | B11: V2.0: Kinematics (solver 3D + schema de hardpoints, Python), validacoes de entrada e aviso Fz<0 (Python). Planilha: 07_KINEMATICS ganha blocos de resultados do solver (N/A) e schema; DR-012; README/Setup atualizados. Nenhuma formula alterada. | C11: Resultados do solver sao cross-check e so entram na planilha com hardpoints reais. As propostas (IC lateral cinematico, %AD com sinal) NAO foram aplicadas as formulas de 06_SUSPENSION. Detalhes em registro-de-versoes-V2.0.md.
A12: 2026-10 | B12: V2.1 PARCIAL: 13_VALIDATION ganha REQ-001 (wheelbase >= 1525 mm) e REQ-002 (razao de bitolas >= 0,75), linhas 28-33; comentario de proveniencia em REQ-003 (B19); README e nota em 04. | C12: Somente adicoes: nenhuma das 84 formulas anteriores foi alterada. REQ-004 e demais resultados dependentes de placeholders NAO foram alterados (aguardam a Decisao A, EDR-025). Mapa de dependencias: placeholder-dependency-map-V2.1.csv.
